Workbook

Sheet Criteria_Pairwise
B1: Usia | C1: Pendapatan | D1: Jaminan | E1: Pekerjaan | G1: Column Sum
A2: Usia | B2: 1 | C2: 0.16666667 | D2: 0.25 | E2: 0.2 | G2: =SUM(B2:B5) -> 13
A3: Pendapatan | B3: 6 | C3: 1 | D3: 1 | E3: 4 | G3: =SUM(C2:C5) -> 2.4166667
A4: Jaminan | B4: 4 | C4: 1 | D4: 1 | E4: 5 | G4: =SUM(D2:D5) -> 2.45
A5: Pekerjaan | B5: 2 | C5: 0.25 | D5: 0.2 | E5: 1 | G5: =SUM(E2:E5) -> 10.2

Sheet Criteria_Normalized
B1: Usia | C1: Pendapatan | D1: Jaminan | E1: Pekerjaan | G1: Weight
A2: Usia | B2: =Criteria_Pairwise!B2/Criteria_Pairwise!G2 -> 0.076923077 | C2: =Criteria_Pairwise!C2/Criteria_Pairwise!G3 -> 0.068965517 | D2: =Criteria_Pairwise!D2/Criteria_Pairwise!G4 -> 0.10204082 | E2: =Criteria_Pairwise!E2/Criteria_Pairwise!G5 -> 0.019607843 | G2: =AVERAGE(B2:E2) -> 0.066884313
A3: Pendapatan | B3: =Criteria_Pairwise!B3/Criteria_Pairwise!G2 -> 0.46153846 | C3: =Criteria_Pairwise!C3/Criteria_Pairwise!G3 -> 0.4137931 | D3: =Criteria_Pairwise!D3/Criteria_Pairwise!G4 -> 0.40816327 | E3: =Criteria_Pairwise!E3/Criteria_Pairwise!G5 -> 0.39215686 | G3: =AVERAGE(B3:E3) -> 0.41891292
A4: Jaminan | B4: =Criteria_Pairwise!B4/Criteria_Pairwise!G2 -> 0.30769231 | C4: =Criteria_Pairwise!C4/Criteria_Pairwise!G3 -> 0.4137931 | D4: =Criteria_Pairwise!D4/Criteria_Pairwise!G4 -> 0.40816327 | E4: =Criteria_Pairwise!E4/Criteria_Pairwise!G5 -> 0.49019608 | G4: =AVERAGE(B4:E4) -> 0.40496119
A5: Pekerjaan | B5: =Criteria_Pairwise!B5/Criteria_Pairwise!G2 -> 0.15384615 | C5: =Criteria_Pairwise!C5/Criteria_Pairwise!G3 -> 0.10344828 | D5: =Criteria_Pairwise!D5/Criteria_Pairwise!G4 -> 0.081632653 | E5: =Criteria_Pairwise!E5/Criteria_Pairwise!G5 -> 0.098039216 | G5: =AVERAGE(B5:E5) -> 0.10924157
G7: =SUMPRODUCT(Criteria_Pairwise!G2:G5,Criteria_Normalized!G2:G5) -> 3.9882879
A8: lambda_max | G8: =IF(G7>0,(G7-4)/(4-1),0) -> -0.0039040181
A9: n | B9: 4
A10: CI | B10: =(G7-B9)/(B9-1) -> -0.0039040181
A11: RI | B11: =CHOOSE(B9,0,0,0.58,0.9,1.12,1.24,1.32,1.41,1.45,1.49) -> 0.9
A12: CR | B12: =IF(B11=0,0,B10/B11) -> -0.0043377979

Sheet Alternatives_Data
A1: Alternative | B1: Usia | C1: Pendapatan | D1: Jaminan | E1: Pekerjaan
A2: Andi | B2: 1 | C2: 2 | D2: 2 | E2: 2
A3: Budi | B3: 2 | C3: 1 | D3: 4 | E3: 4
A4: Citra | B4: 2 | C4: 3 | D4: 3 | E4: 3
A5: Dewi | B5: 2 | C5: 1 | D5: 1 | E5: 1
A6: Eko | B6: 3 | C6: 3 | D6: 2 | E6: 2
A7: Fajar | B7: 1 | C7: 1 | D7: 3 | E7: 2
A8: Gita | B8: 1 | C8: 1 | D8: 4 | E8: 4
A9: Hendra | B9: 3 | C9: 1 | D9: 3 | E9: 3
A10: Intan | B10: 1 | C10: 2 | D10: 1 | E10: 1

Sheet Alternatives_Raw
A1: Alternative | B1: Usia | C1: Pendapatan | D1: Jaminan | E1: Pekerjaan
A2: Andi | B2: 4 | C2: 2 | D2: 2 | E2: 2
A3: Budi | B3: 4 | C3: 4 | D3: 4 | E3: 4
A4: Citra | B4: 4 | C4: 3 | D4: 3 | E4: 3
A5: Dewi | B5: 4 | C5: 1 | D5: 1 | E5: 1
A6: Eko | B6: 4 | C6: 2 | D6: 2 | E6: 2
A7: Fajar | B7: 4 | C7: 2 | D7: 3 | E7: 2
A8: Gita | B8: 3 | C8: 4 | D8: 4 | E8: 4
A9: Hendra | B9: 3 | C9: 3 | D9: 3 | E9: 3
A10: Intan | B10: 4 | C10: 2 | D10: 1 | E10: 1

Sheet Alt_Pairwise_Usia
B1: Andi | C1: Budi | D1: Citra | E1: Dewi | F1: Eko | G1: Fajar | H1: Gita | I1: Hendra | J1: Intan
A2: Andi | B2: =Alternatives_Data!B2/Alternatives_Data!B2 -> 1 | C2: =Alternatives_Data!B2/Alternatives_Data!B3 -> 0.5 | D2: =Alternatives_Data!B2/Alternatives_Data!B4 -> 0.5 | E2: =Alternatives_Data!B2/Alternatives_Data!B5 -> 0.5 | F2: =Alternatives_Data!B2/Alternatives_Data!B6 -> 0.33333333 | G2: =Alternatives_Data!B2/Alternatives_Data!B7 -> 1 | H2: =Alternatives_Data!B2/Alternatives_Data!B8 -> 1 | I2: =Alternatives_Data!B2/Alternatives_Data!B9 -> 0.33333333 | J2: =Alternatives_Data!B2/Alternatives_Data!B10 -> 1
A3: Budi | B3: =Alternatives_Data!B3/Alternatives_Data!B2 -> 2 | C3: =Alternatives_Data!B3/Alternatives_Data!B3 -> 1 | D3: =Alternatives_Data!B3/Alternatives_Data!B4 -> 1 | E3: =Alternatives_Data!B3/Alternatives_Data!B5 -> 1 | F3: =Alternatives_Data!B3/Alternatives_Data!B6 -> 0.66666667 | G3: =Alternatives_Data!B3/Alternatives_Data!B7 -> 2 | H3: =Alternatives_Data!B3/Alternatives_Data!B8 -> 2 | I3: =Alternatives_Data!B3/Alternatives_Data!B9 -> 0.66666667 | J3: =Alternatives_Data!B3/Alternatives_Data!B10 -> 2
A4: Citra | B4: =Alternatives_Data!B4/Alternatives_Data!B2 -> 2 | C4: =Alternatives_Data!B4/Alternatives_Data!B3 -> 1 | D4: =Alternatives_Data!B4/Alternatives_Data!B4 -> 1 | E4: =Alternatives_Data!B4/Alternatives_Data!B5 -> 1 | F4: =Alternatives_Data!B4/Alternatives_Data!B6 -> 0.66666667 | G4: =Alternatives_Data!B4/Alternatives_Data!B7 -> 2 | H4: =Alternatives_Data!B4/Alternatives_Data!B8 -> 2 | I4: =Alternatives_Data!B4/Alternatives_Data!B9 -> 0.66666667 | J4: =Alternatives_Data!B4/Alternatives_Data!B10 -> 2
A5: Dewi | B5: =Alternatives_Data!B5/Alternatives_Data!B2 -> 2 | C5: =Alternatives_Data!B5/Alternatives_Data!B3 -> 1 | D5: =Alternatives_Data!B5/Alternatives_Data!B4 -> 1 | E5: =Alternatives_Data!B5/Alternatives_Data!B5 -> 1 | F5: =Alternatives_Data!B5/Alternatives_Data!B6 -> 0.66666667 | G5: =Alternatives_Data!B5/Alternatives_Data!B7 -> 2 | H5: =Alternatives_Data!B5/Alternatives_Data!B8 -> 2 | I5: =Alternatives_Data!B5/Alternatives_Data!B9 -> 0.66666667 | J5: =Alternatives_Data!B5/Alternatives_Data!B10 -> 2
A6: Eko | B6: =Alternatives_Data!B6/Alternatives_Data!B2 -> 3 | C6: =Alternatives_Data!B6/Alternatives_Data!B3 -> 1.5 | D6: =Alternatives_Data!B6/Alternatives_Data!B4 -> 1.5 | E6: =Alternatives_Data!B6/Alternatives_Data!B5 -> 1.5 | F6: =Alternatives_Data!B6/Alternatives_Data!B6 -> 1 | G6: =Alternatives_Data!B6/Alternatives_Data!B7 -> 3 | H6: =Alternatives_Data!B6/Alternatives_Data!B8 -> 3 | I6: =Alternatives_Data!B6/Alternatives_Data!B9 -> 1 | J6: =Alternatives_Data!B6/Alternatives_Data!B10 -> 3
A7: Fajar | B7: =Alternatives_Data!B7/Alternatives_Data!B2 -> 1 | C7: =Alternatives_Data!B7/Alternatives_Data!B3 -> 0.5 | D7: =Alternatives_Data!B7/Alternatives_Data!B4 -> 0.5 | E7: =Alternatives_Data!B7/Alternatives_Data!B5 -> 0.5 | F7: =Alternatives_Data!B7/Alternatives_Data!B6 -> 0.33333333 | G7: =Alternatives_Data!B7/Alternatives_Data!B7 -> 1 | H7: =Alternatives_Data!B7/Alternatives_Data!B8 -> 1 | I7: =Alternatives_Data!B7/Alternatives_Data!B9 -> 0.33333333 | J7: =Alternatives_Data!B7/Alternatives_Data!B10 -> 1
A8: Gita | B8: =Alternatives_Data!B8/Alternatives_Data!B2 -> 1 | C8: =Alternatives_Data!B8/Alternatives_Data!B3 -> 0.5 | D8: =Alternatives_Data!B8/Alternatives_Data!B4 -> 0.5 | E8: =Alternatives_Data!B8/Alternatives_Data!B5 -> 0.5 | F8: =Alternatives_Data!B8/Alternatives_Data!B6 -> 0.33333333 | G8: =Alternatives_Data!B8/Alternatives_Data!B7 -> 1 | H8: =Alternatives_Data!B8/Alternatives_Data!B8 -> 1 | I8: =Alternatives_Data!B8/Alternatives_Data!B9 -> 0.33333333 | J8: =Alternatives_Data!B8/Alternatives_Data!B10 -> 1
A9: Hendra | B9: =Alternatives_Data!B9/Alternatives_Data!B2 -> 3 | C9: =Alternatives_Data!B9/Alternatives_Data!B3 -> 1.5 | D9: =Alternatives_Data!B9/Alternatives_Data!B4 -> 1.5 | E9: =Alternatives_Data!B9/Alternatives_Data!B5 -> 1.5 | F9: =Alternatives_Data!B9/Alternatives_Data!B6 -> 1 | G9: =Alternatives_Data!B9/Alternatives_Data!B7 -> 3 | H9: =Alternatives_Data!B9/Alternatives_Data!B8 -> 3 | I9: =Alternatives_Data!B9/Alternatives_Data!B9 -> 1 | J9: =Alternatives_Data!B9/Alternatives_Data!B10 -> 3
A10: Intan | B10: =Alternatives_Data!B10/Alternatives_Data!B2 -> 1 | C10: =Alternatives_Data!B10/Alternatives_Data!B3 -> 0.5 | D10: =Alternatives_Data!B10/Alternatives_Data!B4 -> 0.5 | E10: =Alternatives_Data!B10/Alternatives_Data!B5 -> 0.5 | F10: =Alternatives_Data!B10/Alternatives_Data!B6 -> 0.33333333 | G10: =Alternatives_Data!B10/Alternatives_Data!B7 -> 1 | H10: =Alternatives_Data!B10/Alternatives_Data!B8 -> 1 | I10: =Alternatives_Data!B10/Alternatives_Data!B9 -> 0.33333333 | J10: =Alternatives_Data!B10/Alternatives_Data!B10 -> 1

Sheet Alt_Normalized_Usia
B1: Andi | C1: Budi | D1: Citra | E1: Dewi | F1: Eko | G1: Fajar | H1: Gita | I1: Hendra | J1: Intan | K1: Joko | L1: Kiki | M1: Lina | N1: Made | O1: Nisa | P1: Oka | Q1: Putra | R1: Qori | S1: Rian | T1: Sinta | U1: Tono | V1: Uli | W1: Vina | X1: Wahyu | Y1: Xena | Z1: Yoga | AA1: Zaki | AB1: Amanda | AC1: Bayu | AD1: Clara | AE1: Dani | AF1: Alif Adji | AG1: Danu | AH1: Qori Halim | AI1: Dani Wijaya | AJ1: Kiki Suryanto | AK1: Nisa Putri | AL1: Amanda Rahma | AM1: Tono Pratama | AN1: Kiki Putri | AO1: Bayu Irawan | AP1: Qori Putri | AQ1: Gita Irawan | AS1: Local Priority
A2: Andi | B2: =Alt_Pairwise_Usia!B2/Alt_Pairwise_Usia!#REF! -> #REF! | C2: =Alt_Pairwise_Usia!C2/Alt_Pairwise_Usia!#REF! -> #REF! | D2: =Alt_Pairwise_Usia!D2/Alt_Pairwise_Usia!#REF! -> #REF! | E2: =Alt_Pairwise_Usia!E2/Alt_Pairwise_Usia!#REF! -> #REF! | F2: =Alt_Pairwise_Usia!F2/Alt_Pairwise_Usia!#REF! -> #REF! | G2: =Alt_Pairwise_Usia!G2/Alt_Pairwise_Usia!#REF! -> #REF! | H2: =Alt_Pairwise_Usia!H2/Alt_Pairwise_Usia!#REF! -> #REF! | I2: =Alt_Pairwise_Usia!I2/Alt_Pairwise_Usia!#REF! -> #REF! | J2: =Alt_Pairwise_Usia!J2/Alt_Pairwise_Usia!#REF! -> #REF! | K2: =Alt_Pairwise_Usia!#REF!/Alt_Pairwise_Usia!#REF! -> #REF! | L2: =Alt_Pairwise_Usia!#REF!/Alt_Pairwise_Usia!#REF! -> #REF! | M2: =Alt_Pairwise_Usia!#REF!/Alt_Pairwise_Usia!#REF! -> #REF! | N2: =Alt_Pairwise_Usia!#REF!/Alt_Pairwise_Usia!#REF! -> #REF! | O2: =Alt_Pairwise_Usia!#REF!/Alt_Pairwise_Usia!#REF! -> #REF! | P2: =Alt_Pairwise_Usia!#REF!/Alt_Pairwise_Usia!#REF! -> #REF! | Q2: =Alt_Pairwise_Usia!#REF!/Alt_Pairwise_Usia!#REF! -> #REF! | R2: =Alt_Pairwise_Usia!#REF!/Alt_Pairwise_Usia!#REF! -> #REF! | ... AQ2: =Alt_Pairwise_Usia!#REF!/Alt_Pairwise_Usia!#REF! -> #REF! | AS2: =AVERAGE(B2:AQ2) -> #REF!
A3: Budi | B3: =Alt_Pairwise_Usia!B3/Alt_Pairwise_Usia!#REF! -> #REF! | C3: =Alt_Pairwise_Usia!C3/Alt_Pairwise_Usia!#REF! -> #REF! | D3: =Alt_Pairwise_Usia!D3/Alt_Pairwise_Usia!#REF! -> #REF! | E3: =Alt_Pairwise_Usia!E3/Alt_Pairwise_Usia!#REF! -> #REF! | F3: =Alt_Pairwise_Usia!F3/Alt_Pairwise_Usia!#REF! -> #REF! | G3: =Alt_Pairwise_Usia!G3/Alt_Pairwise_Usia!#REF! -> #REF! | H3: =Alt_Pairwise_Usia!H3/Alt_Pairwise_Usia!#REF! -> #REF! | I3: =Alt_Pairwise_Usia!I3/Alt_Pairwise_Usia!#REF! -> #REF! | J3: =Alt_Pairwise_Usia!J3/Alt_Pairwise_Usia!#REF! -> #REF! | K3: =Alt_Pairwise_Usia!#REF!/Alt_Pairwise_Usia!#REF! -> #REF! | L3: =Alt_Pairwise_Usia!#REF!/Alt_Pairwise_Usia!#REF! -> #REF! | M3: =Alt_Pairwise_Usia!#REF!/Alt_Pairwise_Usia!#REF! -> #REF! | N3: =Alt_Pairwise_Usia!#REF!/Alt_Pairwise_Usia!#REF! -> #REF! | O3: =Alt_Pairwise_Usia!#REF!/Alt_Pairwise_Usia!#REF! -> #REF! | P3: =Alt_Pairwise_Usia!#REF!/Alt_Pairwise_Usia!#REF! -> #REF! | Q3: =Alt_Pairwise_Usia!#REF!/Alt_Pairwise_Usia!#REF! -> #REF! | R3: =Alt_Pairwise_Usia!#REF!/Alt_Pairwise_Usia!#REF! -> #REF! | ... AQ3: =Alt_Pairwise_Usia!#REF!/Alt_Pairwise_Usia!#REF! -> #REF! | AS3: =AVERAGE(B3:AQ3) -> #REF!
A4: Citra | B4: =Alt_Pairwise_Usia!B4/Alt_Pairwise_Usia!#REF! -> #REF! | C4: =Alt_Pairwise_Usia!C4/Alt_Pairwise_Usia!#REF! -> #REF! | D4: =Alt_Pairwise_Usia!D4/Alt_Pairwise_Usia!#REF! -> #REF! | E4: =Alt_Pairwise_Usia!E4/Alt_Pairwise_Usia!#REF! -> #REF! | F4: =Alt_Pairwise_Usia!F4/Alt_Pairwise_Usia!#REF! -> #REF! | G4: =Alt_Pairwise_Usia!G4/Alt_Pairwise_Usia!#REF! -> #REF! | H4: =Alt_Pairwise_Usia!H4/Alt_Pairwise_Usia!#REF! -> #REF! | I4: =Alt_Pairwise_Usia!I4/Alt_Pairwise_Usia!#REF! -> #REF! | J4: =Alt_Pairwise_Usia!J4/Alt_Pairwise_Usia!#REF! -> #REF! | K4: =Alt_Pairwise_Usia!#REF!/Alt_Pairwise_Usia!#REF! -> #REF! | L4: =Alt_Pairwise_Usia!#REF!/Alt_Pairwise_Usia!#REF! -> #REF! | M4: =Alt_Pairwise_Usia!#REF!/Alt_Pairwise_Usia!#REF! -> #REF! | N4: =Alt_Pairwise_Usia!#REF!/Alt_Pairwise_Usia!#REF! -> #REF! | O4: =Alt_Pairwise_Usia!#REF!/Alt_Pairwise_Usia!#REF! -> #REF! | P4: =Alt_Pairwise_Usia!#REF!/Alt_Pairwise_Usia!#REF! -> #REF! | Q4: =Alt_Pairwise_Usia!#REF!/Alt_Pairwise_Usia!#REF! -> #REF! | R4: =Alt_Pairwise_Usia!#REF!/Alt_Pairwise_Usia!#REF! -> #REF! | ... AQ4: =Alt_Pairwise_Usia!#REF!/Alt_Pairwise_Usia!#REF! -> #REF! | AS4: =AVERAGE(B4:AQ4) -> #REF!
A5: Dewi | B5: =Alt_Pairwise_Usia!B5/Alt_Pairwise_Usia!#REF! -> #REF! | C5: =Alt_Pairwise_Usia!C5/Alt_Pairwise_Usia!#REF! -> #REF! | D5: =Alt_Pairwise_Usia!D5/Alt_Pairwise_Usia!#REF! -> #REF! | E5: =Alt_Pairwise_Usia!E5/Alt_Pairwise_Usia!#REF! -> #REF! | F5: =Alt_Pairwise_Usia!F5/Alt_Pairwise_Usia!#REF! -> #REF! | G5: =Alt_Pairwise_Usia!G5/Alt_Pairwise_Usia!#REF! -> #REF! | H5: =Alt_Pairwise_Usia!H5/Alt_Pairwise_Usia!#REF! -> #REF! | I5: =Alt_Pairwise_Usia!I5/Alt_Pairwise_Usia!#REF! -> #REF! | J5: =Alt_Pairwise_Usia!J5/Alt_Pairwise_Usia!#REF! -> #REF! | K5: =Alt_Pairwise_Usia!#REF!/Alt_Pairwise_Usia!#REF! -> #REF! | L5: =Alt_Pairwise_Usia!#REF!/Alt_Pairwise_Usia!#REF! -> #REF! | M5: =Alt_Pairwise_Usia!#REF!/Alt_Pairwise_Usia!#REF! -> #REF! | N5: =Alt_Pairwise_Usia!#REF!/Alt_Pairwise_Usia!#REF! -> #REF! | O5: =Alt_Pairwise_Usia!#REF!/Alt_Pairwise_Usia!#REF! -> #REF! | P5: =Alt_Pairwise_Usia!#REF!/Alt_Pairwise_Usia!#REF! -> #REF! | Q5: =Alt_Pairwise_Usia!#REF!/Alt_Pairwise_Usia!#REF! -> #REF! | R5: =Alt_Pairwise_Usia!#REF!/Alt_Pairwise_Usia!#REF! -> #REF! | ... AQ5: =Alt_Pairwise_Usia!#REF!/Alt_Pairwise_Usia!#REF! -> #REF! | AS5: =AVERAGE(B5:AQ5) -> #REF!
A6: Eko | B6: =Alt_Pairwise_Usia!B6/Alt_Pairwise_Usia!#REF! -> #REF! | C6: =Alt_Pairwise_Usia!C6/Alt_Pairwise_Usia!#REF! -> #REF! | D6: =Alt_Pairwise_Usia!D6/Alt_Pairwise_Usia!#REF! -> #REF! | E6: =Alt_Pairwise_Usia!E6/Alt_Pairwise_Usia!#REF! -> #REF! | F6: =Alt_Pairwise_Usia!F6/Alt_Pairwise_Usia!#REF! -> #REF! | G6: =Alt_Pairwise_Usia!G6/Alt_Pairwise_Usia!#REF! -> #REF! | H6: =Alt_Pairwise_Usia!H6/Alt_Pairwise_Usia!#REF! -> #REF! | I6: =Alt_Pairwise_Usia!I6/Alt_Pairwise_Usia!#REF! -> #REF! | J6: =Alt_Pairwise_Usia!J6/Alt_Pairwise_Usia!#REF! -> #REF! | K6: =Alt_Pairwise_Usia!#REF!/Alt_Pairwise_Usia!#REF! -> #REF! | L6: =Alt_Pairwise_Usia!#REF!/Alt_Pairwise_Usia!#REF! -> #REF! | M6: =Alt_Pairwise_Usia!#REF!/Alt_Pairwise_Usia!#REF! -> #REF! | N6: =Alt_Pairwise_Usia!#REF!/Alt_Pairwise_Usia!#REF! -> #REF! | O6: =Alt_Pairwise_Usia!#REF!/Alt_Pairwise_Usia!#REF! -> #REF! | P6: =Alt_Pairwise_Usia!#REF!/Alt_Pairwise_Usia!#REF! -> #REF! | Q6: =Alt_Pairwise_Usia!#REF!/Alt_Pairwise_Usia!#REF! -> #REF! | R6: =Alt_Pairwise_Usia!#REF!/Alt_Pairwise_Usia!#REF! -> #REF! | ... AQ6: =Alt_Pairwise_Usia!#REF!/Alt_Pairwise_Usia!#REF! -> #REF! | AS6: =AVERAGE(B6:AQ6) -> #REF!
A7: Fajar | B7: =Alt_Pairwise_Usia!B7/Alt_Pairwise_Usia!#REF! -> #REF! | C7: =Alt_Pairwise_Usia!C7/Alt_Pairwise_Usia!#REF! -> #REF! | D7: =Alt_Pairwise_Usia!D7/Alt_Pairwise_Usia!#REF! -> #REF! | E7: =Alt_Pairwise_Usia!E7/Alt_Pairwise_Usia!#REF! -> #REF! | F7: =Alt_Pairwise_Usia!F7/Alt_Pairwise_Usia!#REF! -> #REF! | G7: =Alt_Pairwise_Usia!G7/Alt_Pairwise_Usia!#REF! -> #REF! | H7: =Alt_Pairwise_Usia!H7/Alt_Pairwise_Usia!#REF! -> #REF! | I7: =Alt_Pairwise_Usia!I7/Alt_Pairwise_Usia!#REF! -> #REF! | J7: =Alt_Pairwise_Usia!J7/Alt_Pairwise_Usia!#REF! -> #REF! | K7: =Alt_Pairwise_Usia!#REF!/Alt_Pairwise_Usia!#REF! -> #REF! | L7: =Alt_Pairwise_Usia!#REF!/Alt_Pairwise_Usia!#REF! -> #REF! | M7: =Alt_Pairwise_Usia!#REF!/Alt_Pairwise_Usia!#REF! -> #REF! | N7: =Alt_Pairwise_Usia!#REF!/Alt_Pairwise_Usia!#REF! -> #REF! | O7: =Alt_Pairwise_Usia!#REF!/Alt_Pairwise_Usia!#REF! -> #REF! | P7: =Alt_Pairwise_Usia!#REF!/Alt_Pairwise_Usia!#REF! -> #REF! | Q7: =Alt_Pairwise_Usia!#REF!/Alt_Pairwise_Usia!#REF! -> #REF! | R7: =Alt_Pairwise_Usia!#REF!/Alt_Pairwise_Usia!#REF! -> #REF! | ... AQ7: =Alt_Pairwise_Usia!#REF!/Alt_Pairwise_Usia!#REF! -> #REF! | AS7: =AVERAGE(B7:AQ7) -> #REF!
A8: Gita | B8: =Alt_Pairwise_Usia!B8/Alt_Pairwise_Usia!#REF! -> #REF! | C8: =Alt_Pairwise_Usia!C8/Alt_Pairwise_Usia!#REF! -> #REF! | D8: =Alt_Pairwise_Usia!D8/Alt_Pairwise_Usia!#REF! -> #REF! | E8: =Alt_Pairwise_Usia!E8/Alt_Pairwise_Usia!#REF! -> #REF! | F8: =Alt_Pairwise_Usia!F8/Alt_Pairwise_Usia!#REF! -> #REF! | G8: =Alt_Pairwise_Usia!G8/Alt_Pairwise_Usia!#REF! -> #REF! | H8: =Alt_Pairwise_Usia!H8/Alt_Pairwise_Usia!#REF! -> #REF! | I8: =Alt_Pairwise_Usia!I8/Alt_Pairwise_Usia!#REF! -> #REF! | J8: =Alt_Pairwise_Usia!J8/Alt_Pairwise_Usia!#REF! -> #REF! | K8: =Alt_Pairwise_Usia!#REF!/Alt_Pairwise_Usia!#REF! -> #REF! | L8: =Alt_Pairwise_Usia!#REF!/Alt_Pairwise_Usia!#REF! -> #REF! | M8: =Alt_Pairwise_Usia!#REF!/Alt_Pairwise_Usia!#REF! -> #REF! | N8: =Alt_Pairwise_Usia!#REF!/Alt_Pairwise_Usia!#REF! -> #REF! | O8: =Alt_Pairwise_Usia!#REF!/Alt_Pairwise_Usia!#REF! -> #REF! | P8: =Alt_Pairwise_Usia!#REF!/Alt_Pairwise_Usia!#REF! -> #REF! | Q8: =Alt_Pairwise_Usia!#REF!/Alt_Pairwise_Usia!#REF! -> #REF! | R8: =Alt_Pairwise_Usia!#REF!/Alt_Pairwise_Usia!#REF! -> #REF! | ... AQ8: =Alt_Pairwise_Usia!#REF!/Alt_Pairwise_Usia!#REF! -> #REF! | AS8: =AVERAGE(B8:AQ8) -> #REF!
A9: Hendra | B9: =Alt_Pairwise_Usia!B9/Alt_Pairwise_Usia!#REF! -> #REF! | C9: =Alt_Pairwise_Usia!C9/Alt_Pairwise_Usia!#REF! -> #REF! | D9: =Alt_Pairwise_Usia!D9/Alt_Pairwise_Usia!#REF! -> #REF! | E9: =Alt_Pairwise_Usia!E9/Alt_Pairwise_Usia!#REF! -> #REF! | F9: =Alt_Pairwise_Usia!F9/Alt_Pairwise_Usia!#REF! -> #REF! | G9: =Alt_Pairwise_Usia!G9/Alt_Pairwise_Usia!#REF! -> #REF! | H9: =Alt_Pairwise_Usia!H9/Alt_Pairwise_Usia!#REF! -> #REF! | I9: =Alt_Pairwise_Usia!I9/Alt_Pairwise_Usia!#REF! -> #REF! | J9: =Alt_Pairwise_Usia!J9/Alt_Pairwise_Usia!#REF! -> #REF! | K9: =Alt_Pairwise_Usia!#REF!/Alt_Pairwise_Usia!#REF! -> #REF! | L9: =Alt_Pairwise_Usia!#REF!/Alt_Pairwise_Usia!#REF! -> #REF! | M9: =Alt_Pairwise_Usia!#REF!/Alt_Pairwise_Usia!#REF! -> #REF! | N9: =Alt_Pairwise_Usia!#REF!/Alt_Pairwise_Usia!#REF! -> #REF! | O9: =Alt_Pairwise_Usia!#REF!/Alt_Pairwise_Usia!#REF! -> #REF! | P9: =Alt_Pairwise_Usia!#REF!/Alt_Pairwise_Usia!#REF! -> #REF! | Q9: =Alt_Pairwise_Usia!#REF!/Alt_Pairwise_Usia!#REF! -> #REF! | R9: =Alt_Pairwise_Usia!#REF!/Alt_Pairwise_Usia!#REF! -> #REF! | ... AQ9: =Alt_Pairwise_Usia!#REF!/Alt_Pairwise_Usia!#REF! -> #REF! | AS9: =AVERAGE(B9:AQ9) -> #REF!
A10: Intan | B10: =Alt_Pairwise_Usia!B10/Alt_Pairwise_Usia!#REF! -> #REF! | C10: =Alt_Pairwise_Usia!C10/Alt_Pairwise_Usia!#REF! -> #REF! | D10: =Alt_Pairwise_Usia!D10/Alt_Pairwise_Usia!#REF! -> #REF! | E10: =Alt_Pairwise_Usia!E10/Alt_Pairwise_Usia!#REF! -> #REF! | F10: =Alt_Pairwise_Usia!F10/Alt_Pairwise_Usia!#REF! -> #REF! | G10: =Alt_Pairwise_Usia!G10/Alt_Pairwise_Usia!#REF! -> #REF! | H10: =Alt_Pairwise_Usia!H10/Alt_Pairwise_Usia!#REF! -> #REF! | I10: =Alt_Pairwise_Usia!I10/Alt_Pairwise_Usia!#REF! -> #REF! | J10: =Alt_Pairwise_Usia!J10/Alt_Pairwise_Usia!#REF! -> #REF! | K10: =Alt_Pairwise_Usia!#REF!/Alt_Pairwise_Usia!#REF! -> #REF! | L10: =Alt_Pairwise_Usia!#REF!/Alt_Pairwise_Usia!#REF! -> #REF! | M10: =Alt_Pairwise_Usia!#REF!/Alt_Pairwise_Usia!#REF! -> #REF! | N10: =Alt_Pairwise_Usia!#REF!/Alt_Pairwise_Usia!#REF! -> #REF! | O10: =Alt_Pairwise_Usia!#REF!/Alt_Pairwise_Usia!#REF! -> #REF! | P10: =Alt_Pairwise_Usia!#REF!/Alt_Pairwise_Usia!#REF! -> #REF! | Q10: =Alt_Pairwise_Usia!#REF!/Alt_Pairwise_Usia!#REF! -> #REF! | R10: =Alt_Pairwise_Usia!#REF!/Alt_Pairwise_Usia!#REF! -> #REF! | ... AQ10: =Alt_Pairwise_Usia!#REF!/Alt_Pairwise_Usia!#REF! -> #REF! | AS10: =AVERAGE(B10:AQ10) -> #REF!

Sheet Alt_Pairwise_Pendapatan
B1: Andi | C1: Budi | D1: Citra | E1: Dewi | F1: Eko | G1: Fajar | H1: Gita | I1: Hendra | J1: Intan | K1: Joko | L1: Kiki | M1: Lina | N1: Made | O1: Nisa | P1: Oka | Q1: Putra | R1: Qori | S1: Rian | T1: Sinta | U1: Tono | V1: Uli | W1: Vina | X1: Wahyu | Y1: Xena | Z1: Yoga | AA1: Zaki | AB1: Amanda | AC1: Bayu | AD1: Clara | AE1: Dani | AF1: Alif Adji | AG1: Danu | AH1: Qori Halim | AI1: Dani Wijaya | AJ1: Kiki Suryanto | AK1: Nisa Putri | AL1: Amanda Rahma | AM1: Tono Pratama | AN1: Kiki Putri | AO1: Bayu Irawan | AP1: Qori Putri | AQ1: Gita Irawan
A2: Andi | B2: =Alternatives_Data!C2/Alternatives_Data!C2 -> 1 | C2: =Alternatives_Data!C2/Alternatives_Data!C3 -> 2 | D2: =Alternatives_Data!C2/Alternatives_Data!C4 -> 0.66666667 | E2: =Alternatives_Data!C2/Alternatives_Data!C5 -> 2 | F2: =Alternatives_Data!C2/Alternatives_Data!C6 -> 0.66666667 | G2: =Alternatives_Data!C2/Alternatives_Data!C7 -> 2 | H2: =Alternatives_Data!C2/Alternatives_Data!C8 -> 2 | I2: =Alternatives_Data!C2/Alternatives_Data!C9 -> 2 | J2: =Alternatives_Data!C2/Alternatives_Data!C10 -> 1 | K2: =Alternatives_Data!C2/Alternatives_Data!#REF! -> #REF! | L2: =Alternatives_Data!C2/Alternatives_Data!#REF! -> #REF! | M2: =Alternatives_Data!C2/Alternatives_Data!#REF! -> #REF! | N2: =Alternatives_Data!C2/Alternatives_Data!#REF! -> #REF! | O2: =Alternatives_Data!C2/Alternatives_Data!#REF! -> #REF! | P2: =Alternatives_Data!C2/Alternatives_Data!#REF! -> #REF! | Q2: =Alternatives_Data!C2/Alternatives_Data!#REF! -> #REF! | R2: =Alternatives_Data!C2/Alternatives_Data!#REF! -> #REF! | S2: =Alternatives_Data!C2/Alternatives_Data!#REF! -> #REF! | T2: =Alternatives_Data!C2/Alternatives_Data!#REF! -> #REF! | U2: =Alternatives_Data!C2/Alternatives_Data!#REF! -> #REF! | V2: =Alternatives_Data!C2/Alternatives_Data!#REF! -> #REF! | W2: =Alternatives_Data!C2/Alternatives_Data!#REF! -> #REF! | X2: =Alternatives_Data!C2/Alternatives_Data!#REF! -> #REF! | Y2: =Alternatives_Data!C2/Alternatives_Data!#REF! -> #REF! | Z2: =Alternatives_Data!C2/Alternatives_Data!#REF! -> #REF! | AA2: =Alternatives_Data!C2/Alternatives_Data!#REF! -> #REF! | AB2: =Alternatives_Data!C2/Alternatives_Data!#REF! -> #REF! | AC2: =Alternatives_Data!C2/Alternatives_Data!#REF! -> #REF! | AD2: =Alternatives_Data!C2/Alternatives_Data!#REF! -> #REF! | AE2: =Alternatives_Data!C2/Alternatives_Data!#REF! -> #REF! | AF2: =Alternatives_Data!C2/Alternatives_Data!#REF! -> #REF! | AG2: =Alternatives_Data!C2/Alternatives_Data!#REF! -> #REF! | AH2: =Alternatives_Data!C2/Alternatives_Data!#REF! -> #REF! | AI2: =Alternatives_Data!C2/Alternatives_Data!#REF! -> #REF! | AJ2: =Alternatives_Data!C2/Alternatives_Data!#REF! -> #REF! | AK2: =Alternatives_Data!C2/Alternatives_Data!#REF! -> #REF! | AL2: =Alternatives_Data!C2/Alternatives_Data!#REF! -> #REF! | AM2: =Alternatives_Data!C2/Alternatives_Data!#REF! -> #REF! | AN2: =Alternatives_Data!C2/Alternatives_Data!#REF! -> #REF! | AO2: =Alternatives_Data!C2/Alternatives_Data!#REF! -> #REF! | AP2: =Alternatives_Data!C2/Alternatives_Data!#REF! -> #REF! | AQ2: =Alternatives_Data!C2/Alternatives_Data!#REF! -> #REF!
A3: Budi | B3: =Alternatives_Data!C3/Alternatives_Data!C2 -> 0.5 | C3: =Alternatives_Data!C3/Alternatives_Data!C3 -> 1 | D3: =Alternatives_Data!C3/Alternatives_Data!C4 -> 0.33333333 | E3: =Alternatives_Data!C3/Alternatives_Data!C5 -> 1 | F3: =Alternatives_Data!C3/Alternatives_Data!C6 -> 0.33333333 | G3: =Alternatives_Data!C3/Alternatives_Data!C7 -> 1 | H3: =Alternatives_Data!C3/Alternatives_Data!C8 -> 1 | I3: =Alternatives_Data!C3/Alternatives_Data!C9 -> 1 | J3: =Alternatives_Data!C3/Alternatives_Data!C10 -> 0.5 | K3: =Alternatives_Data!C3/Alternatives_Data!#REF! -> #REF! | L3: =Alternatives_Data!C3/Alternatives_Data!#REF! -> #REF! | M3: =Alternatives_Data!C3/Alternatives_Data!#REF! -> #REF! | N3: =Alternatives_Data!C3/Alternatives_Data!#REF! -> #REF! | O3: =Alternatives_Data!C3/Alternatives_Data!#REF! -> #REF! | P3: =Alternatives_Data!C3/Alternatives_Data!#REF! -> #REF! | Q3: =Alternatives_Data!C3/Alternatives_Data!#REF! -> #REF! | R3: =Alternatives_Data!C3/Alternatives_Data!#REF! -> #REF! | S3: =Alternatives_Data!C3/Alternatives_Data!#REF! -> #REF! | T3: =Alternatives_Data!C3/Alternatives_Data!#REF! -> #REF! | U3: =Alternatives_Data!C3/Alternatives_Data!#REF! -> #REF! | V3: =Alternatives_Data!C3/Alternatives_Data!#REF! -> #REF! | W3: =Alternatives_Data!C3/Alternatives_Data!#REF! -> #REF! | X3: =Alternatives_Data!C3/Alternatives_Data!#REF! -> #REF! | Y3: =Alternatives_Data!C3/Alternatives_Data!#REF! -> #REF! | Z3: =Alternatives_Data!C3/Alternatives_Data!#REF! -> #REF! | AA3: =Alternatives_Data!C3/Alternatives_Data!#REF! -> #REF! | AB3: =Alternatives_Data!C3/Alternatives_Data!#REF! -> #REF! | AC3: =Alternatives_Data!C3/Alternatives_Data!#REF! -> #REF! | AD3: =Alternatives_Data!C3/Alternatives_Data!#REF! -> #REF! | AE3: =Alternatives_Data!C3/Alternatives_Data!#REF! -> #REF! | AF3: =Alternatives_Data!C3/Alternatives_Data!#REF! -> #REF! | AG3: =Alternatives_Data!C3/Alternatives_Data!#REF! -> #REF! | AH3: =Alternatives_Data!C3/Alternatives_Data!#REF! -> #REF! | AI3: =Alternatives_Data!C3/Alternatives_Data!#REF! -> #REF! | AJ3: =Alternatives_Data!C3/Alternatives_Data!#REF! -> #REF! | AK3: =Alternatives_Data!C3/Alternatives_Data!#REF! -> #REF! | AL3: =Alternatives_Data!C3/Alternatives_Data!#REF! -> #REF! | AM3: =Alternatives_Data!C3/Alternatives_Data!#REF! -> #REF! | AN3: =Alternatives_Data!C3/Alternatives_Data!#REF! -> #REF! | AO3: =Alternatives_Data!C3/Alternatives_Data!#REF! -> #REF! | AP3: =Alternatives_Data!C3/Alternatives_Data!#REF! -> #REF! | AQ3: =Alternatives_Data!C3/Alternatives_Data!#REF! -> #REF!
A4: Citra | B4: =Alternatives_Data!C4/Alternatives_Data!C2 -> 1.5 | C4: =Alternatives_Data!C4/Alternatives_Data!C3 -> 3 | D4: =Alternatives_Data!C4/Alternatives_Data!C4 -> 1 | E4: =Alternatives_Data!C4/Alternatives_Data!C5 -> 3 | F4: =Alternatives_Data!C4/Alternatives_Data!C6 -> 1 | G4: =Alternatives_Data!C4/Alternatives_Data!C7 -> 3 | H4: =Alternatives_Data!C4/Alternatives_Data!C8 -> 3 | I4: =Alternatives_Data!C4/Alternatives_Data!C9 -> 3 | J4: =Alternatives_Data!C4/Alternatives_Data!C10 -> 1.5 | K4: =Alternatives_Data!C4/Alternatives_Data!#REF! -> #REF! | L4: =Alternatives_Data!C4/Alternatives_Data!#REF! -> #REF! | M4: =Alternatives_Data!C4/Alternatives_Data!#REF! -> #REF! | N4: =Alternatives_Data!C4/Alternatives_Data!#REF! -> #REF! | O4: =Alternatives_Data!C4/Alternatives_Data!#REF! -> #REF! | P4: =Alternatives_Data!C4/Alternatives_Data!#REF! -> #REF! | Q4: =Alternatives_Data!C4/Alternatives_Data!#REF! -> #REF! | R4: =Alternatives_Data!C4/Alternatives_Data!#REF! -> #REF! | S4: =Alternatives_Data!C4/Alternatives_Data!#REF! -> #REF! | T4: =Alternatives_Data!C4/Alternatives_Data!#REF! -> #REF! | U4: =Alternatives_Data!C4/Alternatives_Data!#REF! -> #REF! | V4: =Alternatives_Data!C4/Alternatives_Data!#REF! -> #REF! | W4: =Alternatives_Data!C4/Alternatives_Data!#REF! -> #REF! | X4: =Alternatives_Data!C4/Alternatives_Data!#REF! -> #REF! | Y4: =Alternatives_Data!C4/Alternatives_Data!#REF! -> #REF! | Z4: =Alternatives_Data!C4/Alternatives_Data!#REF! -> #REF! | AA4: =Alternatives_Data!C4/Alternatives_Data!#REF! -> #REF! | AB4: =Alternatives_Data!C4/Alternatives_Data!#REF! -> #REF! | AC4: =Alternatives_Data!C4/Alternatives_Data!#REF! -> #REF! | AD4: =Alternatives_Data!C4/Alternatives_Data!#REF! -> #REF! | AE4: =Alternatives_Data!C4/Alternatives_Data!#REF! -> #REF! | AF4: =Alternatives_Data!C4/Alternatives_Data!#REF! -> #REF! | AG4: =Alternatives_Data!C4/Alternatives_Data!#REF! -> #REF! | AH4: =Alternatives_Data!C4/Alternatives_Data!#REF! -> #REF! | AI4: =Alternatives_Data!C4/Alternatives_Data!#REF! -> #REF! | AJ4: =Alternatives_Data!C4/Alternatives_Data!#REF! -> #REF! | AK4: =Alternatives_Data!C4/Alternatives_Data!#REF! -> #REF! | AL4: =Alternatives_Data!C4/Alternatives_Data!#REF! -> #REF! | AM4: =Alternatives_Data!C4/Alternatives_Data!#REF! -> #REF! | AN4: =Alternatives_Data!C4/Alternatives_Data!#REF! -> #REF! | AO4: =Alternatives_Data!C4/Alternatives_Data!#REF! -> #REF! | AP4: =Alternatives_Data!C4/Alternatives_Data!#REF! -> #REF! | AQ4: =Alternatives_Data!C4/Alternatives_Data!#REF! -> #REF!
A5: Dewi | B5: =Alternatives_Data!C5/Alternatives_Data!C2 -> 0.5 | C5: =Alternatives_Data!C5/Alternatives_Data!C3 -> 1 | D5: =Alternatives_Data!C5/Alternatives_Data!C4 -> 0.33333333 | E5: =Alternatives_Data!C5/Alternatives_Data!C5 -> 1 | F5: =Alternatives_Data!C5/Alternatives_Data!C6 -> 0.33333333 | G5: =Alternatives_Data!C5/Alternatives_Data!C7 -> 1 | H5: =Alternatives_Data!C5/Alternatives_Data!C8 -> 1 | I5: =Alternatives_Data!C5/Alternatives_Data!C9 -> 1 | J5: =Alternatives_Data!C5/Alternatives_Data!C10 -> 0.5 | K5: =Alternatives_Data!C5/Alternatives_Data!#REF! -> #REF! | L5: =Alternatives_Data!C5/Alternatives_Data!#REF! -> #REF! | M5: =Alternatives_Data!C5/Alternatives_Data!#REF! -> #REF! | N5: =Alternatives_Data!C5/Alternatives_Data!#REF! -> #REF! | O5: =Alternatives_Data!C5/Alternatives_Data!#REF! -> #REF! | P5: =Alternatives_Data!C5/Alternatives_Data!#REF! -> #REF! | Q5: =Alternatives_Data!C5/Alternatives_Data!#REF! -> #REF! | R5: =Alternatives_Data!C5/Alternatives_Data!#REF! -> #REF! | S5: =Alternatives_Data!C5/Alternatives_Data!#REF! -> #REF! | T5: =Alternatives_Data!C5/Alternatives_Data!#REF! -> #REF! | U5: =Alternatives_Data!C5/Alternatives_Data!#REF! -> #REF! | V5: =Alternatives_Data!C5/Alternatives_Data!#REF! -> #REF! | W5: =Alternatives_Data!C5/Alternatives_Data!#REF! -> #REF! | X5: =Alternatives_Data!C5/Alternatives_Data!#REF! -> #REF! | Y5: =Alternatives_Data!C5/Alternatives_Data!#REF! -> #REF! | Z5: =Alternatives_Data!C5/Alternatives_Data!#REF! -> #REF! | AA5: =Alternatives_Data!C5/Alternatives_Data!#REF! -> #REF! | AB5: =Alternatives_Data!C5/Alternatives_Data!#REF! -> #REF! | AC5: =Alternatives_Data!C5/Alternatives_Data!#REF! -> #REF! | AD5: =Alternatives_Data!C5/Alternatives_Data!#REF! -> #REF! | AE5: =Alternatives_Data!C5/Alternatives_Data!#REF! -> #REF! | AF5: =Alternatives_Data!C5/Alternatives_Data!#REF! -> #REF! | AG5: =Alternatives_Data!C5/Alternatives_Data!#REF! -> #REF! | AH5: =Alternatives_Data!C5/Alternatives_Data!#REF! -> #REF! | AI5: =Alternatives_Data!C5/Alternatives_Data!#REF! -> #REF! | AJ5: =Alternatives_Data!C5/Alternatives_Data!#REF! -> #REF! | AK5: =Alternatives_Data!C5/Alternatives_Data!#REF! -> #REF! | AL5: =Alternatives_Data!C5/Alternatives_Data!#REF! -> #REF! | AM5: =Alternatives_Data!C5/Alternatives_Data!#REF! -> #REF! | AN5: =Alternatives_Data!C5/Alternatives_Data!#REF! -> #REF! | AO5: =Alternatives_Data!C5/Alternatives_Data!#REF! -> #REF! | AP5: =Alternatives_Data!C5/Alternatives_Data!#REF! -> #REF! | AQ5: =Alternatives_Data!C5/Alternatives_Data!#REF! -> #REF!
A6: Eko | B6: =Alternatives_Data!C6/Alternatives_Data!C2 -> 1.5 | C6: =Alternatives_Data!C6/Alternatives_Data!C3 -> 3 | D6: =Alternatives_Data!C6/Alternatives_Data!C4 -> 1 | E6: =Alternatives_Data!C6/Alternatives_Data!C5 -> 3 | F6: =Alternatives_Data!C6/Alternatives_Data!C6 -> 1 | G6: =Alternatives_Data!C6/Alternatives_Data!C7 -> 3 | H6: =Alternatives_Data!C6/Alternatives_Data!C8 -> 3 | I6: =Alternatives_Data!C6/Alternatives_Data!C9 -> 3 | J6: =Alternatives_Data!C6/Alternatives_Data!C10 -> 1.5 | K6: =Alternatives_Data!C6/Alternatives_Data!#REF! -> #REF! | L6: =Alternatives_Data!C6/Alternatives_Data!#REF! -> #REF! | M6: =Alternatives_Data!C6/Alternatives_Data!#REF! -> #REF! | N6: =Alternatives_Data!C6/Alternatives_Data!#REF! -> #REF! | O6: =Alternatives_Data!C6/Alternatives_Data!#REF! -> #REF! | P6: =Alternatives_Data!C6/Alternatives_Data!#REF! -> #REF! | Q6: =Alternatives_Data!C6/Alternatives_Data!#REF! -> #REF! | R6: =Alternatives_Data!C6/Alternatives_Data!#REF! -> #REF! | S6: =Alternatives_Data!C6/Alternatives_Data!#REF! -> #REF! | T6: =Alternatives_Data!C6/Alternatives_Data!#REF! -> #REF! | U6: =Alternatives_Data!C6/Alternatives_Data!#REF! -> #REF! | V6: =Alternatives_Data!C6/Alternatives_Data!#REF! -> #REF! | W6: =Alternatives_Data!C6/Alternatives_Data!#REF! -> #REF! | X6: =Alternatives_Data!C6/Alternatives_Data!#REF! -> #REF! | Y6: =Alternatives_Data!C6/Alternatives_Data!#REF! -> #REF! | Z6: =Alternatives_Data!C6/Alternatives_Data!#REF! -> #REF! | AA6: =Alternatives_Data!C6/Alternatives_Data!#REF! -> #REF! | AB6: =Alternatives_Data!C6/Alternatives_Data!#REF! -> #REF! | AC6: =Alternatives_Data!C6/Alternatives_Data!#REF! -> #REF! | AD6: =Alternatives_Data!C6/Alternatives_Data!#REF! -> #REF! | AE6: =Alternatives_Data!C6/Alternatives_Data!#REF! -> #REF! | AF6: =Alternatives_Data!C6/Alternatives_Data!#REF! -> #REF! | AG6: =Alternatives_Data!C6/Alternatives_Data!#REF! -> #REF! | AH6: =Alternatives_Data!C6/Alternatives_Data!#REF! -> #REF! | AI6: =Alternatives_Data!C6/Alternatives_Data!#REF! -> #REF! | AJ6: =Alternatives_Data!C6/Alternatives_Data!#REF! -> #REF! | AK6: =Alternatives_Data!C6/Alternatives_Data!#REF! -> #REF! | AL6: =Alternatives_Data!C6/Alternatives_Data!#REF! -> #REF! | AM6: =Alternatives_Data!C6/Alternatives_Data!#REF! -> #REF! | AN6: =Alternatives_Data!C6/Alternatives_Data!#REF! -> #REF! | AO6: =Alternatives_Data!C6/Alternatives_Data!#REF! -> #REF! | AP6: =Alternatives_Data!C6/Alternatives_Data!#REF! -> #REF! | AQ6: =Alternatives_Data!C6/Alternatives_Data!#REF! -> #REF!
A7: Fajar | B7: =Alternatives_Data!C7/Alternatives_Data!C2 -> 0.5 | C7: =Alternatives_Data!C7/Alternatives_Data!C3 -> 1 | D7: =Alternatives_Data!C7/Alternatives_Data!C4 -> 0.33333333 | E7: =Alternatives_Data!C7/Alternatives_Data!C5 -> 1 | F7: =Alternatives_Data!C7/Alternatives_Data!C6 -> 0.33333333 | G7: =Alternatives_Data!C7/Alternatives_Data!C7 -> 1 | H7: =Alternatives_Data!C7/Alternatives_Data!C8 -> 1 | I7: =Alternatives_Data!C7/Alternatives_Data!C9 -> 1 | J7: =Alternatives_Data!C7/Alternatives_Data!C10 -> 0.5 | K7: =Alternatives_Data!C7/Alternatives_Data!#REF! -> #REF! | L7: =Alternatives_Data!C7/Alternatives_Data!#REF! -> #REF! | M7: =Alternatives_Data!C7/Alternatives_Data!#REF! -> #REF! | N7: =Alternatives_Data!C7/Alternatives_Data!#REF! -> #REF! | O7: =Alternatives_Data!C7/Alternatives_Data!#REF! -> #REF! | P7: =Alternatives_Data!C7/Alternatives_Data!#REF! -> #REF! | Q7: =Alternatives_Data!C7/Alternatives_Data!#REF! -> #REF! | R7: =Alternatives_Data!C7/Alternatives_Data!#REF! -> #REF! | S7: =Alternatives_Data!C7/Alternatives_Data!#REF! -> #REF! | T7: =Alternatives_Data!C7/Alternatives_Data!#REF! -> #REF! | U7: =Alternatives_Data!C7/Alternatives_Data!#REF! -> #REF! | V7: =Alternatives_Data!C7/Alternatives_Data!#REF! -> #REF! | W7: =Alternatives_Data!C7/Alternatives_Data!#REF! -> #REF! | X7: =Alternatives_Data!C7/Alternatives_Data!#REF! -> #REF! | Y7: =Alternatives_Data!C7/Alternatives_Data!#REF! -> #REF! | Z7: =Alternatives_Data!C7/Alternatives_Data!#REF! -> #REF! | AA7: =Alternatives_Data!C7/Alternatives_Data!#REF! -> #REF! | AB7: =Alternatives_Data!C7/Alternatives_Data!#REF! -> #REF! | AC7: =Alternatives_Data!C7/Alternatives_Data!#REF! -> #REF! | AD7: =Alternatives_Data!C7/Alternatives_Data!#REF! -> #REF! | AE7: =Alternatives_Data!C7/Alternatives_Data!#REF! -> #REF! | AF7: =Alternatives_Data!C7/Alternatives_Data!#REF! -> #REF! | AG7: =Alternatives_Data!C7/Alternatives_Data!#REF! -> #REF! | AH7: =Alternatives_Data!C7/Alternatives_Data!#REF! -> #REF! | AI7: =Alternatives_Data!C7/Alternatives_Data!#REF! -> #REF! | AJ7: =Alternatives_Data!C7/Alternatives_Data!#REF! -> #REF! | AK7: =Alternatives_Data!C7/Alternatives_Data!#REF! -> #REF! | AL7: =Alternatives_Data!C7/Alternatives_Data!#REF! -> #REF! | AM7: =Alternatives_Data!C7/Alternatives_Data!#REF! -> #REF! | AN7: =Alternatives_Data!C7/Alternatives_Data!#REF! -> #REF! | AO7: =Alternatives_Data!C7/Alternatives_Data!#REF! -> #REF! | AP7: =Alternatives_Data!C7/Alternatives_Data!#REF! -> #REF! | AQ7: =Alternatives_Data!C7/Alternatives_Data!#REF! -> #REF!
A8: Gita | B8: =Alternatives_Data!C8/Alternatives_Data!C2 -> 0.5 | C8: =Alternatives_Data!C8/Alternatives_Data!C3 -> 1 | D8: =Alternatives_Data!C8/Alternatives_Data!C4 -> 0.33333333 | E8: =Alternatives_Data!C8/Alternatives_Data!C5 -> 1 | F8: =Alternatives_Data!C8/Alternatives_Data!C6 -> 0.33333333 | G8: =Alternatives_Data!C8/Alternatives_Data!C7 -> 1 | H8: =Alternatives_Data!C8/Alternatives_Data!C8 -> 1 | I8: =Alternatives_Data!C8/Alternatives_Data!C9 -> 1 | J8: =Alternatives_Data!C8/Alternatives_Data!C10 -> 0.5 | K8: =Alternatives_Data!C8/Alternatives_Data!#REF! -> #REF! | L8: =Alternatives_Data!C8/Alternatives_Data!#REF! -> #REF! | M8: =Alternatives_Data!C8/Alternatives_Data!#REF! -> #REF! | N8: =Alternatives_Data!C8/Alternatives_Data!#REF! -> #REF! | O8: =Alternatives_Data!C8/Alternatives_Data!#REF! -> #REF! | P8: =Alternatives_Data!C8/Alternatives_Data!#REF! -> #REF! | Q8: =Alternatives_Data!C8/Alternatives_Data!#REF! -> #REF! | R8: =Alternatives_Data!C8/Alternatives_Data!#REF! -> #REF! | S8: =Alternatives_Data!C8/Alternatives_Data!#REF! -> #REF! | T8: =Alternatives_Data!C8/Alternatives_Data!#REF! -> #REF! | U8: =Alternatives_Data!C8/Alternatives_Data!#REF! -> #REF! | V8: =Alternatives_Data!C8/Alternatives_Data!#REF! -> #REF! | W8: =Alternatives_Data!C8/Alternatives_Data!#REF! -> #REF! | X8: =Alternatives_Data!C8/Alternatives_Data!#REF! -> #REF! | Y8: =Alternatives_Data!C8/Alternatives_Data!#REF! -> #REF! | Z8: =Alternatives_Data!C8/Alternatives_Data!#REF! -> #REF! | AA8: =Alternatives_Data!C8/Alternatives_Data!#REF! -> #REF! | AB8: =Alternatives_Data!C8/Alternatives_Data!#REF! -> #REF! | AC8: =Alternatives_Data!C8/Alternatives_Data!#REF! -> #REF! | AD8: =Alternatives_Data!C8/Alternatives_Data!#REF! -> #REF! | AE8: =Alternatives_Data!C8/Alternatives_Data!#REF! -> #REF! | AF8: =Alternatives_Data!C8/Alternatives_Data!#REF! -> #REF! | AG8: =Alternatives_Data!C8/Alternatives_Data!#REF! -> #REF! | AH8: =Alternatives_Data!C8/Alternatives_Data!#REF! -> #REF! | AI8: =Alternatives_Data!C8/Alternatives_Data!#REF! -> #REF! | AJ8: =Alternatives_Data!C8/Alternatives_Data!#REF! -> #REF! | AK8: =Alternatives_Data!C8/Alternatives_Data!#REF! -> #REF! | AL8: =Alternatives_Data!C8/Alternatives_Data!#REF! -> #REF! | AM8: =Alternatives_Data!C8/Alternatives_Data!#REF! -> #REF! | AN8: =Alternatives_Data!C8/Alternatives_Data!#REF! -> #REF! | AO8: =Alternatives_Data!C8/Alternatives_Data!#REF! -> #REF! | AP8: =Alternatives_Data!C8/Alternatives_Data!#REF! -> #REF! | AQ8: =Alternatives_Data!C8/Alternatives_Data!#REF! -> #REF!
A9: Hendra | B9: =Alternatives_Data!C9/Alternatives_Data!C2 -> 0.5 | C9: =Alternatives_Data!C9/Alternatives_Data!C3 -> 1 | D9: =Alternatives_Data!C9/Alternatives_Data!C4 -> 0.33333333 | E9: =Alternatives_Data!C9/Alternatives_Data!C5 -> 1 | F9: =Alternatives_Data!C9/Alternatives_Data!C6 -> 0.33333333 | G9: =Alternatives_Data!C9/Alternatives_Data!C7 -> 1 | H9: =Alternatives_Data!C9/Alternatives_Data!C8 -> 1 | I9: =Alternatives_Data!C9/Alternatives_Data!C9 -> 1 | J9: =Alternatives_Data!C9/Alternatives_Data!C10 -> 0.5 | K9: =Alternatives_Data!C9/Alternatives_Data!#REF! -> #REF! | L9: =Alternatives_Data!C9/Alternatives_Data!#REF! -> #REF! | M9: =Alternatives_Data!C9/Alternatives_Data!#REF! -> #REF! | N9: =Alternatives_Data!C9/Alternatives_Data!#REF! -> #REF! | O9: =Alternatives_Data!C9/Alternatives_Data!#REF! -> #REF! | P9: =Alternatives_Data!C9/Alternatives_Data!#REF! -> #REF! | Q9: =Alternatives_Data!C9/Alternatives_Data!#REF! -> #REF! | R9: =Alternatives_Data!C9/Alternatives_Data!#REF! -> #REF! | S9: =Alternatives_Data!C9/Alternatives_Data!#REF! -> #REF! | T9: =Alternatives_Data!C9/Alternatives_Data!#REF! -> #REF! | U9: =Alternatives_Data!C9/Alternatives_Data!#REF! -> #REF! | V9: =Alternatives_Data!C9/Alternatives_Data!#REF! -> #REF! | W9: =Alternatives_Data!C9/Alternatives_Data!#REF! -> #REF! | X9: =Alternatives_Data!C9/Alternatives_Data!#REF! -> #REF! | Y9: =Alternatives_Data!C9/Alternatives_Data!#REF! -> #REF! | Z9: =Alternatives_Data!C9/Alternatives_Data!#REF! -> #REF! | AA9: =Alternatives_Data!C9/Alternatives_Data!#REF! -> #REF! | AB9: =Alternatives_Data!C9/Alternatives_Data!#REF! -> #REF! | AC9: =Alternatives_Data!C9/Alternatives_Data!#REF! -> #REF! | AD9: =Alternatives_Data!C9/Alternatives_Data!#REF! -> #REF! | AE9: =Alternatives_Data!C9/Alternatives_Data!#REF! -> #REF! | AF9: =Alternatives_Data!C9/Alternatives_Data!#REF! -> #REF! | AG9: =Alternatives_Data!C9/Alternatives_Data!#REF! -> #REF! | AH9: =Alternatives_Data!C9/Alternatives_Data!#REF! -> #REF! | AI9: =Alternatives_Data!C9/Alternatives_Data!#REF! -> #REF! | AJ9: =Alternatives_Data!C9/Alternatives_Data!#REF! -> #REF! | AK9: =Alternatives_Data!C9/Alternatives_Data!#REF! -> #REF! | AL9: =Alternatives_Data!C9/Alternatives_Data!#REF! -> #REF! | AM9: =Alternatives_Data!C9/Alternatives_Data!#REF! -> #REF! | AN9: =Alternatives_Data!C9/Alternatives_Data!#REF! -> #REF! | AO9: =Alternatives_Data!C9/Alternatives_Data!#REF! -> #REF! | AP9: =Alternatives_Data!C9/Alternatives_Data!#REF! -> #REF! | AQ9: =Alternatives_Data!C9/Alternatives_Data!#REF! -> #REF!
A10: Intan | B10: =Alternatives_Data!C10/Alternatives_Data!C2 -> 1 | C10: =Alternatives_Data!C10/Alternatives_Data!C3 -> 2 | D10: =Alternatives_Data!C10/Alternatives_Data!C4 -> 0.66666667 | E10: =Alternatives_Data!C10/Alternatives_Data!C5 -> 2 | F10: =Alternatives_Data!C10/Alternatives_Data!C6 -> 0.66666667 | G10: =Alternatives_Data!C10/Alternatives_Data!C7 -> 2 | H10: =Alternatives_Data!C10/Alternatives_Data!C8 -> 2 | I10: =Alternatives_Data!C10/Alternatives_Data!C9 -> 2 | J10: =Alternatives_Data!C10/Alternatives_Data!C10 -> 1 | K10: =Alternatives_Data!C10/Alternatives_Data!#REF! -> #REF! | L10: =Alternatives_Data!C10/Alternatives_Data!#REF! -> #REF! | M10: =Alternatives_Data!C10/Alternatives_Data!#REF! -> #REF! | N10: =Alternatives_Data!C10/Alternatives_Data!#REF! -> #REF! | O10: =Alternatives_Data!C10/Alternatives_Data!#REF! -> #REF! | P10: =Alternatives_Data!C10/Alternatives_Data!#REF! -> #REF! | Q10: =Alternatives_Data!C10/Alternatives_Data!#REF! -> #REF! | R10: =Alternatives_Data!C10/Alternatives_Data!#REF! -> #REF! | S10: =Alternatives_Data!C10/Alternatives_Data!#REF! -> #REF! | T10: =Alternatives_Data!C10/Alternatives_Data!#REF! -> #REF! | U10: =Alternatives_Data!C10/Alternatives_Data!#REF! -> #REF! | V10: =Alternatives_Data!C10/Alternatives_Data!#REF! -> #REF! | W10: =Alternatives_Data!C10/Alternatives_Data!#REF! -> #REF! | X10: =Alternatives_Data!C10/Alternatives_Data!#REF! -> #REF! | Y10: =Alternatives_Data!C10/Alternatives_Data!#REF! -> #REF! | Z10: =Alternatives_Data!C10/Alternatives_Data!#REF! -> #REF! | AA10: =Alternatives_Data!C10/Alternatives_Data!#REF! -> #REF! | AB10: =Alternatives_Data!C10/Alternatives_Data!#REF! -> #REF! | AC10: =Alternatives_Data!C10/Alternatives_Data!#REF! -> #REF! | AD10: =Alternatives_Data!C10/Alternatives_Data!#REF! -> #REF! | AE10: =Alternatives_Data!C10/Alternatives_Data!#REF! -> #REF! | AF10: =Alternatives_Data!C10/Alternatives_Data!#REF! -> #REF! | AG10: =Alternatives_Data!C10/Alternatives_Data!#REF! -> #REF! | AH10: =Alternatives_Data!C10/Alternatives_Data!#REF! -> #REF! | AI10: =Alternatives_Data!C10/Alternatives_Data!#REF! -> #REF! | AJ10: =Alternatives_Data!C10/Alternatives_Data!#REF! -> #REF! | AK10: =Alternatives_Data!C10/Alternatives_Data!#REF! -> #REF! | AL10: =Alternatives_Data!C10/Alternatives_Data!#REF! -> #REF! | AM10: =Alternatives_Data!C10/Alternatives_Data!#REF! -> #REF! | AN10: =Alternatives_Data!C10/Alternatives_Data!#REF! -> #REF! | AO10: =Alternatives_Data!C10/Alternatives_Data!#REF! -> #REF! | AP10: =Alternatives_Data!C10/Alternatives_Data!#REF! -> #REF! | AQ10: =Alternatives_Data!C10/Alternatives_Data!#REF! -> #REF!
A11: Joko | B11: =Alternatives_Data!#REF!/Alternatives_Data!C2 -> #REF! | C11: =Alternatives_Data!#REF!/Alternatives_Data!C3 -> #REF! | D11: =Alternatives_Data!#REF!/Alternatives_Data!C4 -> #REF! | E11: =Alternatives_Data!#REF!/Alternatives_Data!C5 -> #REF! | F11: =Alternatives_Data!#REF!/Alternatives_Data!C6 -> #REF! | G11: =Alternatives_Data!#REF!/Alternatives_Data!C7 -> #REF! | H11: =Alternatives_Data!#REF!/Alternatives_Data!C8 -> #REF! | I11: =Alternatives_Data!#REF!/Alternatives_Data!C9 -> #REF! | J11: =Alternatives_Data!#REF!/Alternatives_Data!C10 -> #REF! | K11: =Alternatives_Data!#REF!/Alternatives_Data!#REF! -> #REF! | L11: =Alternatives_Data!#REF!/Alternatives_Data!#REF! -> #REF! | M11: =Alternatives_Data!#REF!/Alternatives_Data!#REF! -> #REF! | N11: =Alternatives_Data!#REF!/Alternatives_Data!#REF! -> #REF! | O11: =Alternatives_Data!#REF!/Alternatives_Data!#REF! -> #REF! | P11: =Alternatives_Data!#REF!/Alternatives_Data!#REF! -> #REF! | Q11: =Alternatives_Data!#REF!/Alternatives_Data!#REF! -> #REF! | R11: =Alternatives_Data!#REF!/Alternatives_Data!#REF! -> #REF! | ... AQ11: =Alternatives_Data!#REF!/Alternatives_Data!#REF! -> #REF!
A12: Kiki | B12: =Alternatives_Data!#REF!/Alternatives_Data!C2 -> #REF! | C12: =Alternatives_Data!#REF!/Alternatives_Data!C3 -> #REF! | D12: =Alternatives_Data!#REF!/Alternatives_Data!C4 -> #REF! | E12: =Alternatives_Data!#REF!/Alternatives_Data!C5 -> #REF! | F12: =Alternatives_Data!#REF!/Alternatives_Data!C6 -> #REF! | G12: =Alternatives_Data!#REF!/Alternatives_Data!C7 -> #REF! | H12: =Alternatives_Data!#REF!/Alternatives_Data!C8 -> #REF! | I12: =Alternatives_Data!#REF!/Alternatives_Data!C9 -> #REF! | J12: =Alternatives_Data!#REF!/Alternatives_Data!C10 -> #REF! | K12: =Alternatives_Data!#REF!/Alternatives_Data!#REF! -> #REF! | L12: =Alternatives_Data!#REF!/Alternatives_Data!#REF! -> #REF! | M12: =Alternatives_Data!#REF!/Alternatives_Data!#REF! -> #REF! | N12: =Alternatives_Data!#REF!/Alternatives_Data!#REF! -> #REF! | O12: =Alternatives_Data!#REF!/Alternatives_Data!#REF! -> #REF! | P12: =Alternatives_Data!#REF!/Alternatives_Data!#REF! -> #REF! | Q12: =Alternatives_Data!#REF!/Alternatives_Data!#REF! -> #REF! | R12: =Alternatives_Data!#REF!/Alternatives_Data!#REF! -> #REF! | ... AQ12: =Alternatives_Data!#REF!/Alternatives_Data!#REF! -> #REF!
A13: Lina | B13: =Alternatives_Data!#REF!/Alternatives_Data!C2 -> #REF! | C13: =Alternatives_Data!#REF!/Alternatives_Data!C3 -> #REF! | D13: =Alternatives_Data!#REF!/Alternatives_Data!C4 -> #REF! | E13: =Alternatives_Data!#REF!/Alternatives_Data!C5 -> #REF! | F13: =Alternatives_Data!#REF!/Alternatives_Data!C6 -> #REF! | G13: =Alternatives_Data!#REF!/Alternatives_Data!C7 -> #REF! | H13: =Alternatives_Data!#REF!/Alternatives_Data!C8 -> #REF! | I13: =Alternatives_Data!#REF!/Alternatives_Data!C9 -> #REF! | J13: =Alternatives_Data!#REF!/Alternatives_Data!C10 -> #REF! | K13: =Alternatives_Data!#REF!/Alternatives_Data!#REF! -> #REF! | L13: =Alternatives_Data!#REF!/Alternatives_Data!#REF! -> #REF! | M13: =Alternatives_Data!#REF!/Alternatives_Data!#REF! -> #REF! | N13: =Alternatives_Data!#REF!/Alternatives_Data!#REF! -> #REF! | O13: =Alternatives_Data!#REF!/Alternatives_Data!#REF! -> #REF! | P13: =Alternatives_Data!#REF!/Alternatives_Data!#REF! -> #REF! | Q13: =Alternatives_Data!#REF!/Alternatives_Data!#REF! -> #REF! | R13: =Alternatives_Data!#REF!/Alternatives_Data!#REF! -> #REF! | ... AQ13: =Alternatives_Data!#REF!/Alternatives_Data!#REF! -> #REF!
A14: Made | B14: =Alternatives_Data!#REF!/Alternatives_Data!C2 -> #REF! | C14: =Alternatives_Data!#REF!/Alternatives_Data!C3 -> #REF! | D14: =Alternatives_Data!#REF!/Alternatives_Data!C4 -> #REF! | E14: =Alternatives_Data!#REF!/Alternatives_Data!C5 -> #REF! | F14: =Alternatives_Data!#REF!/Alternatives_Data!C6 -> #REF! | G14: =Alternatives_Data!#REF!/Alternatives_Data!C7 -> #REF! | H14: =Alternatives_Data!#REF!/Alternatives_Data!C8 -> #REF! | I14: =Alternatives_Data!#REF!/Alternatives_Data!C9 -> #REF! | J14: =Alternatives_Data!#REF!/Alternatives_Data!C10 -> #REF! | K14: =Alternatives_Data!#REF!/Alternatives_Data!#REF! -> #REF! | L14: =Alternatives_Data!#REF!/Alternatives_Data!#REF! -> #REF! | M14: =Alternatives_Data!#REF!/Alternatives_Data!#REF! -> #REF! | N14: =Alternatives_Data!#REF!/Alternatives_Data!#REF! -> #REF! | O14: =Alternatives_Data!#REF!/Alternatives_Data!#REF! -> #REF! | P14: =Alternatives_Data!#REF!/Alternatives_Data!#REF! -> #REF! | Q14: =Alternatives_Data!#REF!/Alternatives_Data!#REF! -> #REF! | R14: =Alternatives_Data!#REF!/Alternatives_Data!#REF! -> #REF! | ... AQ14: =Alternatives_Data!#REF!/Alternatives_Data!#REF! -> #REF!
A15: Nisa | B15: =Alternatives_Data!#REF!/Alternatives_Data!C2 -> #REF! | C15: =Alternatives_Data!#REF!/Alternatives_Data!C3 -> #REF! | D15: =Alternatives_Data!#REF!/Alternatives_Data!C4 -> #REF! | E15: =Alternatives_Data!#REF!/Alternatives_Data!C5 -> #REF! | F15: =Alternatives_Data!#REF!/Alternatives_Data!C6 -> #REF! | G15: =Alternatives_Data!#REF!/Alternatives_Data!C7 -> #REF! | H15: =Alternatives_Data!#REF!/Alternatives_Data!C8 -> #REF! | I15: =Alternatives_Data!#REF!/Alternatives_Data!C9 -> #REF! | J15: =Alternatives_Data!#REF!/Alternatives_Data!C10 -> #REF! | K15: =Alternatives_Data!#REF!/Alternatives_Data!#REF! -> #REF! | L15: =Alternatives_Data!#REF!/Alternatives_Data!#REF! -> #REF! | M15: =Alternatives_Data!#REF!/Alternatives_Data!#REF! -> #REF! | N15: =Alternatives_Data!#REF!/Alternatives_Data!#REF! -> #REF! | O15: =Alternatives_Data!#REF!/Alternatives_Data!#REF! -> #REF! | P15: =Alternatives_Data!#REF!/Alternatives_Data!#REF! -> #REF! | Q15: =Alternatives_Data!#REF!/Alternatives_Data!#REF! -> #REF! | R15: =Alternatives_Data!#REF!/Alternatives_Data!#REF! -> #REF! | ... AQ15: =Alternatives_Data!#REF!/Alternatives_Data!#REF! -> #REF!
A16: Oka | B16: =Alternatives_Data!#REF!/Alternatives_Data!C2 -> #REF! | C16: =Alternatives_Data!#REF!/Alternatives_Data!C3 -> #REF! | D16: =Alternatives_Data!#REF!/Alternatives_Data!C4 -> #REF! | E16: =Alternatives_Data!#REF!/Alternatives_Data!C5 -> #REF! | F16: =Alternatives_Data!#REF!/Alternatives_Data!C6 -> #REF! | G16: =Alternatives_Data!#REF!/Alternatives_Data!C7 -> #REF! | H16: =Alternatives_Data!#REF!/Alternatives_Data!C8 -> #REF! | I16: =Alternatives_Data!#REF!/Alternatives_Data!C9 -> #REF! | J16: =Alternatives_Data!#REF!/Alternatives_Data!C10 -> #REF! | K16: =Alternatives_Data!#REF!/Alternatives_Data!#REF! -> #REF! | L16: =Alternatives_Data!#REF!/Alternatives_Data!#REF! -> #REF! | M16: =Alternatives_Data!#REF!/Alternatives_Data!#REF! -> #REF! | N16: =Alternatives_Data!#REF!/Alternatives_Data!#REF! -> #REF! | O16: =Alternatives_Data!#REF!/Alternatives_Data!#REF! -> #REF! | P16: =Alternatives_Data!#REF!/Alternatives_Data!#REF! -> #REF! | Q16: =Alternatives_Data!#REF!/Alternatives_Data!#REF! -> #REF! | R16: =Alternatives_Data!#REF!/Alternatives_Data!#REF! -> #REF! | ... AQ16: =Alternatives_Data!#REF!/Alternatives_Data!#REF! -> #REF!
A17: Putra | B17: =Alternatives_Data!#REF!/Alternatives_Data!C2 -> #REF! | C17: =Alternatives_Data!#REF!/Alternatives_Data!C3 -> #REF! | D17: =Alternatives_Data!#REF!/Alternatives_Data!C4 -> #REF! | E17: =Alternatives_Data!#REF!/Alternatives_Data!C5 -> #REF! | F17: =Alternatives_Data!#REF!/Alternatives_Data!C6 -> #REF! | G17: =Alternatives_Data!#REF!/Alternatives_Data!C7 -> #REF! | H17: =Alternatives_Data!#REF!/Alternatives_Data!C8 -> #REF! | I17: =Alternatives_Data!#REF!/Alternatives_Data!C9 -> #REF! | J17: =Alternatives_Data!#REF!/Alternatives_Data!C10 -> #REF! | K17: =Alternatives_Data!#REF!/Alternatives_Data!#REF! -> #REF! | L17: =Alternatives_Data!#REF!/Alternatives_Data!#REF! -> #REF! | M17: =Alternatives_Data!#REF!/Alternatives_Data!#REF! -> #REF! | N17: =Alternatives_Data!#REF!/Alternatives_Data!#REF! -> #REF! | O17: =Alternatives_Data!#REF!/Alternatives_Data!#REF! -> #REF! | P17: =Alternatives_Data!#REF!/Alternatives_Data!#REF! -> #REF! | Q17: =Alternatives_Data!#REF!/Alternatives_Data!#REF! -> #REF! | R17: =Alternatives_Data!#REF!/Alternatives_Data!#REF! -> #REF! | ... AQ17: =Alternatives_Data!#REF!/Alternatives_Data!#REF! -> #REF!
A18: Qori | B18: =Alternatives_Data!#REF!/Alternatives_Data!C2 -> #REF! | C18: =Alternatives_Data!#REF!/Alternatives_Data!C3 -> #REF! | D18: =Alternatives_Data!#REF!/Alternatives_Data!C4 -> #REF! | E18: =Alternatives_Data!#REF!/Alternatives_Data!C5 -> #REF! | F18: =Alternatives_Data!#REF!/Alternatives_Data!C6 -> #REF! | G18: =Alternatives_Data!#REF!/Alternatives_Data!C7 -> #REF! | H18: =Alternatives_Data!#REF!/Alternatives_Data!C8 -> #REF! | I18: =Alternatives_Data!#REF!/Alternatives_Data!C9 -> #REF! | J18: =Alternatives_Data!#REF!/Alternatives_Data!C10 -> #REF! | K18: =Alternatives_Data!#REF!/Alternatives_Data!#REF! -> #REF! | L18: =Alternatives_Data!#REF!/Alternatives_Data!#REF! -> #REF! | M18: =Alternatives_Data!#REF!/Alternatives_Data!#REF! -> #REF! | N18: =Alternatives_Data!#REF!/Alternatives_Data!#REF! -> #REF! | O18: =Alternatives_Data!#REF!/Alternatives_Data!#REF! -> #REF! | P18: =Alternatives_Data!#REF!/Alternatives_Data!#REF! -> #REF! | Q18: =Alternatives_Data!#REF!/Alternatives_Data!#REF! -> #REF! | R18: =Alternatives_Data!#REF!/Alternatives_Data!#REF! -> #REF! | ... AQ18: =Alternatives_Data!#REF!/Alternatives_Data!#REF! -> #REF!
A19: Rian | B19: =Alternatives_Data!#REF!/Alternatives_Data!C2 -> #REF! | C19: =Alternatives_Data!#REF!/Alternatives_Data!C3 -> #REF! | D19: =Alternatives_Data!#REF!/Alternatives_Data!C4 -> #REF! | E19: =Alternatives_Data!#REF!/Alternatives_Data!C5 -> #REF! | F19: =Alternatives_Data!#REF!/Alternatives_Data!C6 -> #REF! | G19: =Alternatives_Data!#REF!/Alternatives_Data!C7 -> #REF! | H19: =Alternatives_Data!#REF!/Alternatives_Data!C8 -> #REF! | I19: =Alternatives_Data!#REF!/Alternatives_Data!C9 -> #REF! | J19: =Alternatives_Data!#REF!/Alternatives_Data!C10 -> #REF! | K19: =Alternatives_Data!#REF!/Alternatives_Data!#REF! -> #REF! | L19: =Alternatives_Data!#REF!/Alternatives_Data!#REF! -> #REF! | M19: =Alternatives_Data!#REF!/Alternatives_Data!#REF! -> #REF! | N19: =Alternatives_Data!#REF!/Alternatives_Data!#REF! -> #REF! | O19: =Alternatives_Data!#REF!/Alternatives_Data!#REF! -> #REF! | P19: =Alternatives_Data!#REF!/Alternatives_Data!#REF! -> #REF! | Q19: =Alternatives_Data!#REF!/Alternatives_Data!#REF! -> #REF! | R19: =Alternatives_Data!#REF!/Alternatives_Data!#REF! -> #REF! | ... AQ19: =Alternatives_Data!#REF!/Alternatives_Data!#REF! -> #REF!
A20: Sinta | B20: =Alternatives_Data!#REF!/Alternatives_Data!C2 -> #REF! | C20: =Alternatives_Data!#REF!/Alternatives_Data!C3 -> #REF! | D20: =Alternatives_Data!#REF!/Alternatives_Data!C4 -> #REF! | E20: =Alternatives_Data!#REF!/Alternatives_Data!C5 -> #REF! | F20: =Alternatives_Data!#REF!/Alternatives_Data!C6 -> #REF! | G20: =Alternatives_Data!#REF!/Alternatives_Data!C7 -> #REF! | H20: =Alternatives_Data!#REF!/Alternatives_Data!C8 -> #REF! | I20: =Alternatives_Data!#REF!/Alternatives_Data!C9 -> #REF! | J20: =Alternatives_Data!#REF!/Alternatives_Data!C10 -> #REF! | K20: =Alternatives_Data!#REF!/Alternatives_Data!#REF! -> #REF! | L20: =Alternatives_Data!#REF!/Alternatives_Data!#REF! -> #REF! | M20: =Alternatives_Data!#REF!/Alternatives_Data!#REF! -> #REF! | N20: =Alternatives_Data!#REF!/Alternatives_Data!#REF! -> #REF! | O20: =Alternatives_Data!#REF!/Alternatives_Data!#REF! -> #REF! | P20: =Alternatives_Data!#REF!/Alternatives_Data!#REF! -> #REF! | Q20: =Alternatives_Data!#REF!/Alternatives_Data!#REF! -> #REF! | R20: =Alternatives_Data!#REF!/Alternatives_Data!#REF! -> #REF! | ... AQ20: =Alternatives_Data!#REF!/Alternatives_Data!#REF! -> #REF!
A21: Tono | B21: =Alternatives_Data!#REF!/Alternatives_Data!C2 -> #REF! | C21: =Alternatives_Data!#REF!/Alternatives_Data!C3 -> #REF! | D21: =Alternatives_Data!#REF!/Alternatives_Data!C4 -> #REF! | E21: =Alternatives_Data!#REF!/Alternatives_Data!C5 -> #REF! | F21: =Alternatives_Data!#REF!/Alternatives_Data!C6 -> #REF! | G21: =Alternatives_Data!#REF!/Alternatives_Data!C7 -> #REF! | H21: =Alternatives_Data!#REF!/Alternatives_Data!C8 -> #REF! | I21: =Alternatives_Data!#REF!/Alternatives_Data!C9 -> #REF! | J21: =Alternatives_Data!#REF!/Alternatives_Data!C10 -> #REF! | K21: =Alternatives_Data!#REF!/Alternatives_Data!#REF! -> #REF! | L21: =Alternatives_Data!#REF!/Alternatives_Data!#REF! -> #REF! | M21: =Alternatives_Data!#REF!/Alternatives_Data!#REF! -> #REF! | N21: =Alternatives_Data!#REF!/Alternatives_Data!#REF! -> #REF! | O21: =Alternatives_Data!#REF!/Alternatives_Data!#REF! -> #REF! | P21: =Alternatives_Data!#REF!/Alternatives_Data!#REF! -> #REF! | Q21: =Alternatives_Data!#REF!/Alternatives_Data!#REF! -> #REF! | R21: =Alternatives_Data!#REF!/Alternatives_Data!#REF! -> #REF! | ... AQ21: =Alternatives_Data!#REF!/Alternatives_Data!#REF! -> #REF!
A22: Uli | B22: =Alternatives_Data!#REF!/Alternatives_Data!C2 -> #REF! | C22: =Alternatives_Data!#REF!/Alternatives_Data!C3 -> #REF! | D22: =Alternatives_Data!#REF!/Alternatives_Data!C4 -> #REF! | E22: =Alternatives_Data!#REF!/Alternatives_Data!C5 -> #REF! | F22: =Alternatives_Data!#REF!/Alternatives_Data!C6 -> #REF! | G22: =Alternatives_Data!#REF!/Alternatives_Data!C7 -> #REF! | H22: =Alternatives_Data!#REF!/Alternatives_Data!C8 -> #REF! | I22: =Alternatives_Data!#REF!/Alternatives_Data!C9 -> #REF! | J22: =Alternatives_Data!#REF!/Alternatives_Data!C10 -> #REF! | K22: =Alternatives_Data!#REF!/Alternatives_Data!#REF! -> #REF! | L22: =Alternatives_Data!#REF!/Alternatives_Data!#REF! -> #REF! | M22: =Alternatives_Data!#REF!/Alternatives_Data!#REF! -> #REF! | N22: =Alternatives_Data!#REF!/Alternatives_Data!#REF! -> #REF! | O22: =Alternatives_Data!#REF!/Alternatives_Data!#REF! -> #REF! | P22: =Alternatives_Data!#REF!/Alternatives_Data!#REF! -> #REF! | Q22: =Alternatives_Data!#REF!/Alternatives_Data!#REF! -> #REF! | R22: =Alternatives_Data!#REF!/Alternatives_Data!#REF! -> #REF! | ... AQ22: =Alternatives_Data!#REF!/Alternatives_Data!#REF! -> #REF!
A23: Vina | B23: =Alternatives_Data!#REF!/Alternatives_Data!C2 -> #REF! | C23: =Alternatives_Data!#REF!/Alternatives_Data!C3 -> #REF! | D23: =Alternatives_Data!#REF!/Alternatives_Data!C4 -> #REF! | E23: =Alternatives_Data!#REF!/Alternatives_Data!C5 -> #REF! | F23: =Alternatives_Data!#REF!/Alternatives_Data!C6 -> #REF! | G23: =Alternatives_Data!#REF!/Alternatives_Data!C7 -> #REF! | H23: =Alternatives_Data!#REF!/Alternatives_Data!C8 -> #REF! | I23: =Alternatives_Data!#REF!/Alternatives_Data!C9 -> #REF! | J23: =Alternatives_Data!#REF!/Alternatives_Data!C10 -> #REF! | K23: =Alternatives_Data!#REF!/Alternatives_Data!#REF! -> #REF! | L23: =Alternatives_Data!#REF!/Alternatives_Data!#REF! -> #REF! | M23: =Alternatives_Data!#REF!/Alternatives_Data!#REF! -> #REF! | N23: =Alternatives_Data!#REF!/Alternatives_Data!#REF! -> #REF! | O23: =Alternatives_Data!#REF!/Alternatives_Data!#REF! -> #REF! | P23: =Alternatives_Data!#REF!/Alternatives_Data!#REF! -> #REF! | Q23: =Alternatives_Data!#REF!/Alternatives_Data!#REF! -> #REF! | R23: =Alternatives_Data!#REF!/Alternatives_Data!#REF! -> #REF! | ... AQ23: =Alternatives_Data!#REF!/Alternatives_Data!#REF! -> #REF!
A24: Wahyu | B24: =Alternatives_Data!#REF!/Alternatives_Data!C2 -> #REF! | C24: =Alternatives_Data!#REF!/Alternatives_Data!C3 -> #REF! | D24: =Alternatives_Data!#REF!/Alternatives_Data!C4 -> #REF! | E24: =Alternatives_Data!#REF!/Alternatives_Data!C5 -> #REF! | F24: =Alternatives_Data!#REF!/Alternatives_Data!C6 -> #REF! | G24: =Alternatives_Data!#REF!/Alternatives_Data!C7 -> #REF! | H24: =Alternatives_Data!#REF!/Alternatives_Data!C8 -> #REF! | I24: =Alternatives_Data!#REF!/Alternatives_Data!C9 -> #REF! | J24: =Alternatives_Data!#REF!/Alternatives_Data!C10 -> #REF! | K24: =Alternatives_Data!#REF!/Alternatives_Data!#REF! -> #REF! | L24: =Alternatives_Data!#REF!/Alternatives_Data!#REF! -> #REF! | M24: =Alternatives_Data!#REF!/Alternatives_Data!#REF! -> #REF! | N24: =Alternatives_Data!#REF!/Alternatives_Data!#REF! -> #REF! | O24: =Alternatives_Data!#REF!/Alternatives_Data!#REF! -> #REF! | P24: =Alternatives_Data!#REF!/Alternatives_Data!#REF! -> #REF! | Q24: =Alternatives_Data!#REF!/Alternatives_Data!#REF! -> #REF! | R24: =Alternatives_Data!#REF!/Alternatives_Data!#REF! -> #REF! | ... AQ24: =Alternatives_Data!#REF!/Alternatives_Data!#REF! -> #REF!
A25: Xena | B25: =Alternatives_Data!#REF!/Alternatives_Data!C2 -> #REF! | C25: =Alternatives_Data!#REF!/Alternatives_Data!C3 -> #REF! | D25: =Alternatives_Data!#REF!/Alternatives_Data!C4 -> #REF! | E25: =Alternatives_Data!#REF!/Alternatives_Data!C5 -> #REF! | F25: =Alternatives_Data!#REF!/Alternatives_Data!C6 -> #REF! | G25: =Alternatives_Data!#REF!/Alternatives_Data!C7 -> #REF! | H25: =Alternatives_Data!#REF!/Alternatives_Data!C8 -> #REF! | I25: =Alternatives_Data!#REF!/Alternatives_Data!C9 -> #REF! | J25: =Alternatives_Data!#REF!/Alternatives_Data!C10 -> #REF! | K25: =Alternatives_Data!#REF!/Alternatives_Data!#REF! -> #REF! | L25: =Alternatives_Data!#REF!/Alternatives_Data!#REF! -> #REF! | M25: =Alternatives_Data!#REF!/Alternatives_Data!#REF! -> #REF! | N25: =Alternatives_Data!#REF!/Alternatives_Data!#REF! -> #REF! | O25: =Alternatives_Data!#REF!/Alternatives_Data!#REF! -> #REF! | P25: =Alternatives_Data!#REF!/Alternatives_Data!#REF! -> #REF! | Q25: =Alternatives_Data!#REF!/Alternatives_Data!#REF! -> #REF! | R25: =Alternatives_Data!#REF!/Alternatives_Data!#REF! -> #REF! | ... AQ25: =Alternatives_Data!#REF!/Alternatives_Data!#REF! -> #REF!
