Workbook

Sheet Criteria_Pairwise
B1: Usia | C1: Pendapatan | D1: Jaminan | E1: Pekerjaan
A2: Usia | B2: 1 | C2: 1 | D2: 1 | E2: 1
A3: Pendapatan | B3: 1 | C3: 1 | D3: 1 | E3: 1
A4: Jaminan | B4: 1 | C4: 1 | D4: 1 | E4: 1
A5: Pekerjaan | B5: 1 | C5: 1 | D5: 1 | E5: 1
A7: Column Sum | B7: =SUM(B2:B5) | C7: =SUM(C2:C5) | D7: =SUM(D2:D5) | E7: =SUM(E2:E5)

Sheet Criteria_Normalized
B1: Usia | C1: Pendapatan | D1: Jaminan | E1: Pekerjaan | G1: Weight
A2: Usia | B2: =Criteria_Pairwise!B2/Criteria_Pairwise!B7 | C2: =Criteria_Pairwise!C2/Criteria_Pairwise!C7 | D2: =Criteria_Pairwise!D2/Criteria_Pairwise!D7 | E2: =Criteria_Pairwise!E2/Criteria_Pairwise!E7 | G2: =AVERAGE(B2:E2)
A3: Pendapatan | B3: =Criteria_Pairwise!B3/Criteria_Pairwise!B7 | C3: =Criteria_Pairwise!C3/Criteria_Pairwise!C7 | D3: =Criteria_Pairwise!D3/Criteria_Pairwise!D7 | E3: =Criteria_Pairwise!E3/Criteria_Pairwise!E7 | G3: =AVERAGE(B3:E3)
A4: Jaminan | B4: =Criteria_Pairwise!B4/Criteria_Pairwise!B7 | C4: =Criteria_Pairwise!C4/Criteria_Pairwise!C7 | D4: =Criteria_Pairwise!D4/Criteria_Pairwise!D7 | E4: =Criteria_Pairwise!E4/Criteria_Pairwise!E7 | G4: =AVERAGE(B4:E4)
A5: Pekerjaan | B5: =Criteria_Pairwise!B5/Criteria_Pairwise!B7 | C5: =Criteria_Pairwise!C5/Criteria_Pairwise!C7 | D5: =Criteria_Pairwise!D5/Criteria_Pairwise!D7 | E5: =Criteria_Pairwise!E5/Criteria_Pairwise!E7 | G5: =AVERAGE(B5:E5)
G7: =SUMPRODUCT(Criteria_Pairwise!B7:E7,G2:G5)
A8: lambda_max
A9: n | B9: 4
A10: CI | B10: =(G7-B9)/(B9-1)
A11: RI | B11: =CHOOSE(B9,0,0,0.58,0.90,1.12,1.24,1.32,1.41,1.45,1.49)
A12: CR | B12: =IF(B11=0,0,B10/B11)

Sheet Alternatives_Data
A1: Alternative | B1: Usia | C1: Pendapatan | D1: Jaminan | E1: Pekerjaan
A2: Andi | B2: 1 | C2: 1 | D2: 2 | E2: 2
A3: Budi | B3: 1 | C3: 1 | D3: 4 | E3: 4
A4: Citra | B4: 1 | C4: 1 | D4: 3 | E4: 3
A5: Dewi | B5: 1 | C5: 1 | D5: 1 | E5: 1
A6: Eko | B6: 1 | C6: 1 | D6: 2 | E6: 2
A7: Fajar | B7: 1 | C7: 1 | D7: 3 | E7: 2
A8: Gita | B8: 1 | C8: 1 | D8: 4 | E8: 4
A9: Hendra | B9: 1 | C9: 1 | D9: 3 | E9: 3
A10: Intan | B10: 1 | C10: 1 | D10: 1 | E10: 1
A11: Joko | B11: 1 | C11: 1 | D11: 2 | E11: 2
A12: Kiki | B12: 1 | C12: 1 | D12: 3 | E12: 2
A13: Lina | B13: 1 | C13: 1 | D13: 4 | E13: 3
... A43: Gita Irawan | B43: 1 | C43: 1 | D43: 3 | E43: 2

Sheet Alternatives_Raw
A1: Alternative | B1: Usia | C1: Pendapatan | D1: Jaminan | E1: Pekerjaan
A2: Andi | B2: 4 | C2: 2 | D2: 2 | E2: 2
A3: Budi | B3: 4 | C3: 4 | D3: 4 | E3: 4
A4: Citra | B4: 4 | C4: 3 | D4: 3 | E4: 3
A5: Dewi | B5: 4 | C5: 1 | D5: 1 | E5: 1
A6: Eko | B6: 4 | C6: 2 | D6: 2 | E6: 2
A7: Fajar | B7: 4 | C7: 2 | D7: 3 | E7: 2
A8: Gita | B8: 3 | C8: 4 | D8: 4 | E8: 4
A9: Hendra | B9: 3 | C9: 3 | D9: 3 | E9: 3
A10: Intan | B10: 4 | C10: 2 | D10: 1 | E10: 1
A11: Joko | B11: 4 | C11: 2 | D11: 2 | E11: 2
A12: Kiki | B12: 4 | C12: 2 | D12: 3 | E12: 2
A13: Lina | B13: 4 | C13: 3 | D13: 4 | E13: 3
... A43: Gita Irawan | B43: 4 | C43: 3 | D43: 3 | E43: 2

Sheet Alt_Pairwise_Usia
B1: Andi | C1: Budi | D1: Citra | E1: Dewi | F1: Eko | G1: Fajar | H1: Gita | I1: Hendra | J1: Intan | K1: Joko | L1: Kiki | M1: Lina | N1: Made | O1: Nisa | P1: Oka | Q1: Putra | R1: Qori | S1: Rian | T1: Sinta | U1: Tono | V1: Uli | W1: Vina | X1: Wahyu | Y1: Xena | Z1: Yoga | AA1: Zaki | AB1: Amanda | AC1: Bayu | AD1: Clara | AE1: Dani | AF1: Alif Adji | AG1: Danu | AH1: Qori Halim | AI1: Dani Wijaya | AJ1: Kiki Suryanto | AK1: Nisa Putri | AL1: Amanda Rahma | AM1: Tono Pratama | AN1: Kiki Putri | AO1: Bayu Irawan | AP1: Qori Putri | AQ1: Gita Irawan
A2: Andi | B2: =Alternatives_Data!B2/Alternatives_Data!B2 | C2: =Alternatives_Data!B2/Alternatives_Data!B3 | D2: =Alternatives_Data!B2/Alternatives_Data!B4 | E2: =Alternatives_Data!B2/Alternatives_Data!B5 | F2: =Alternatives_Data!B2/Alternatives_Data!B6 | G2: =Alternatives_Data!B2/Alternatives_Data!B7 | H2: =Alternatives_Data!B2/Alternatives_Data!B8 | I2: =Alternatives_Data!B2/Alternatives_Data!B9 | J2: =Alternatives_Data!B2/Alternatives_Data!B10 | K2: =Alternatives_Data!B2/Alternatives_Data!B11 | L2: =Alternatives_Data!B2/Alternatives_Data!B12 | M2: =Alternatives_Data!B2/Alternatives_Data!B13 | N2: =Alternatives_Data!B2/Alternatives_Data!B14 | O2: =Alternatives_Data!B2/Alternatives_Data!B15 | P2: =Alternatives_Data!B2/Alternatives_Data!B16 | Q2: =Alternatives_Data!B2/Alternatives_Data!B17 | R2: =Alternatives_Data!B2/Alternatives_Data!B18 | S2: =Alternatives_Data!B2/Alternatives_Data!B19 | T2: =Alternatives_Data!B2/Alternatives_Data!B20 | U2: =Alternatives_Data!B2/Alternatives_Data!B21 | V2: =Alternatives_Data!B2/Alternatives_Data!B22 | W2: =Alternatives_Data!B2/Alternatives_Data!B23 | X2: =Alternatives_Data!B2/Alternatives_Data!B24 | Y2: =Alternatives_Data!B2/Alternatives_Data!B25 | Z2: =Alternatives_Data!B2/Alternatives_Data!B26 | AA2: =Alternatives_Data!B2/Alternatives_Data!B27 | AB2: =Alternatives_Data!B2/Alternatives_Data!B28 | AC2: =Alternatives_Data!B2/Alternatives_Data!B29 | AD2: =Alternatives_Data!B2/Alternatives_Data!B30 | AE2: =Alternatives_Data!B2/Alternatives_Data!B31 | AF2: =Alternatives_Data!B2/Alternatives_Data!B32 | AG2: =Alternatives_Data!B2/Alternatives_Data!B33 | AH2: =Alternatives_Data!B2/Alternatives_Data!B34 | AI2: =Alternatives_Data!B2/Alternatives_Data!B35 | AJ2: =Alternatives_Data!B2/Alternatives_Data!B36 | AK2: =Alternatives_Data!B2/Alternatives_Data!B37 | AL2: =Alternatives_Data!B2/Alternatives_Data!B38 | AM2: =Alternatives_Data!B2/Alternatives_Data!B39 | AN2: =Alternatives_Data!B2/Alternatives_Data!B40 | AO2: =Alternatives_Data!B2/Alternatives_Data!B41 | AP2: =Alternatives_Data!B2/Alternatives_Data!B42 | AQ2: =Alternatives_Data!B2/Alternatives_Data!B43
A3: Budi | B3: =Alternatives_Data!B3/Alternatives_Data!B2 | C3: =Alternatives_Data!B3/Alternatives_Data!B3 | D3: =Alternatives_Data!B3/Alternatives_Data!B4 | E3: =Alternatives_Data!B3/Alternatives_Data!B5 | F3: =Alternatives_Data!B3/Alternatives_Data!B6 | G3: =Alternatives_Data!B3/Alternatives_Data!B7 | H3: =Alternatives_Data!B3/Alternatives_Data!B8 | I3: =Alternatives_Data!B3/Alternatives_Data!B9 | J3: =Alternatives_Data!B3/Alternatives_Data!B10 | K3: =Alternatives_Data!B3/Alternatives_Data!B11 | L3: =Alternatives_Data!B3/Alternatives_Data!B12 | M3: =Alternatives_Data!B3/Alternatives_Data!B13 | N3: =Alternatives_Data!B3/Alternatives_Data!B14 | O3: =Alternatives_Data!B3/Alternatives_Data!B15 | P3: =Alternatives_Data!B3/Alternatives_Data!B16 | Q3: =Alternatives_Data!B3/Alternatives_Data!B17 | R3: =Alternatives_Data!B3/Alternatives_Data!B18 | S3: =Alternatives_Data!B3/Alternatives_Data!B19 | T3: =Alternatives_Data!B3/Alternatives_Data!B20 | U3: =Alternatives_Data!B3/Alternatives_Data!B21 | V3: =Alternatives_Data!B3/Alternatives_Data!B22 | W3: =Alternatives_Data!B3/Alternatives_Data!B23 | X3: =Alternatives_Data!B3/Alternatives_Data!B24 | Y3: =Alternatives_Data!B3/Alternatives_Data!B25 | Z3: =Alternatives_Data!B3/Alternatives_Data!B26 | AA3: =Alternatives_Data!B3/Alternatives_Data!B27 | AB3: =Alternatives_Data!B3/Alternatives_Data!B28 | AC3: =Alternatives_Data!B3/Alternatives_Data!B29 | AD3: =Alternatives_Data!B3/Alternatives_Data!B30 | AE3: =Alternatives_Data!B3/Alternatives_Data!B31 | AF3: =Alternatives_Data!B3/Alternatives_Data!B32 | AG3: =Alternatives_Data!B3/Alternatives_Data!B33 | AH3: =Alternatives_Data!B3/Alternatives_Data!B34 | AI3: =Alternatives_Data!B3/Alternatives_Data!B35 | AJ3: =Alternatives_Data!B3/Alternatives_Data!B36 | AK3: =Alternatives_Data!B3/Alternatives_Data!B37 | AL3: =Alternatives_Data!B3/Alternatives_Data!B38 | AM3: =Alternatives_Data!B3/Alternatives_Data!B39 | AN3: =Alternatives_Data!B3/Alternatives_Data!B40 | AO3: =Alternatives_Data!B3/Alternatives_Data!B41 | AP3: =Alternatives_Data!B3/Alternatives_Data!B42 | AQ3: =Alternatives_Data!B3/Alternatives_Data!B43
A4: Citra | B4: =Alternatives_Data!B4/Alternatives_Data!B2 | C4: =Alternatives_Data!B4/Alternatives_Data!B3 | D4: =Alternatives_Data!B4/Alternatives_Data!B4 | E4: =Alternatives_Data!B4/Alternatives_Data!B5 | F4: =Alternatives_Data!B4/Alternatives_Data!B6 | G4: =Alternatives_Data!B4/Alternatives_Data!B7 | H4: =Alternatives_Data!B4/Alternatives_Data!B8 | I4: =Alternatives_Data!B4/Alternatives_Data!B9 | J4: =Alternatives_Data!B4/Alternatives_Data!B10 | K4: =Alternatives_Data!B4/Alternatives_Data!B11 | L4: =Alternatives_Data!B4/Alternatives_Data!B12 | M4: =Alternatives_Data!B4/Alternatives_Data!B13 | N4: =Alternatives_Data!B4/Alternatives_Data!B14 | O4: =Alternatives_Data!B4/Alternatives_Data!B15 | P4: =Alternatives_Data!B4/Alternatives_Data!B16 | Q4: =Alternatives_Data!B4/Alternatives_Data!B17 | R4: =Alternatives_Data!B4/Alternatives_Data!B18 | S4: =Alternatives_Data!B4/Alternatives_Data!B19 | T4: =Alternatives_Data!B4/Alternatives_Data!B20 | U4: =Alternatives_Data!B4/Alternatives_Data!B21 | V4: =Alternatives_Data!B4/Alternatives_Data!B22 | W4: =Alternatives_Data!B4/Alternatives_Data!B23 | X4: =Alternatives_Data!B4/Alternatives_Data!B24 | Y4: =Alternatives_Data!B4/Alternatives_Data!B25 | Z4: =Alternatives_Data!B4/Alternatives_Data!B26 | AA4: =Alternatives_Data!B4/Alternatives_Data!B27 | AB4: =Alternatives_Data!B4/Alternatives_Data!B28 | AC4: =Alternatives_Data!B4/Alternatives_Data!B29 | AD4: =Alternatives_Data!B4/Alternatives_Data!B30 | AE4: =Alternatives_Data!B4/Alternatives_Data!B31 | AF4: =Alternatives_Data!B4/Alternatives_Data!B32 | AG4: =Alternatives_Data!B4/Alternatives_Data!B33 | AH4: =Alternatives_Data!B4/Alternatives_Data!B34 | AI4: =Alternatives_Data!B4/Alternatives_Data!B35 | AJ4: =Alternatives_Data!B4/Alternatives_Data!B36 | AK4: =Alternatives_Data!B4/Alternatives_Data!B37 | AL4: =Alternatives_Data!B4/Alternatives_Data!B38 | AM4: =Alternatives_Data!B4/Alternatives_Data!B39 | AN4: =Alternatives_Data!B4/Alternatives_Data!B40 | AO4: =Alternatives_Data!B4/Alternatives_Data!B41 | AP4: =Alternatives_Data!B4/Alternatives_Data!B42 | AQ4: =Alternatives_Data!B4/Alternatives_Data!B43
A5: Dewi | B5: =Alternatives_Data!B5/Alternatives_Data!B2 | C5: =Alternatives_Data!B5/Alternatives_Data!B3 | D5: =Alternatives_Data!B5/Alternatives_Data!B4 | E5: =Alternatives_Data!B5/Alternatives_Data!B5 | F5: =Alternatives_Data!B5/Alternatives_Data!B6 | G5: =Alternatives_Data!B5/Alternatives_Data!B7 | H5: =Alternatives_Data!B5/Alternatives_Data!B8 | I5: =Alternatives_Data!B5/Alternatives_Data!B9 | J5: =Alternatives_Data!B5/Alternatives_Data!B10 | K5: =Alternatives_Data!B5/Alternatives_Data!B11 | L5: =Alternatives_Data!B5/Alternatives_Data!B12 | M5: =Alternatives_Data!B5/Alternatives_Data!B13 | N5: =Alternatives_Data!B5/Alternatives_Data!B14 | O5: =Alternatives_Data!B5/Alternatives_Data!B15 | P5: =Alternatives_Data!B5/Alternatives_Data!B16 | Q5: =Alternatives_Data!B5/Alternatives_Data!B17 | R5: =Alternatives_Data!B5/Alternatives_Data!B18 | S5: =Alternatives_Data!B5/Alternatives_Data!B19 | T5: =Alternatives_Data!B5/Alternatives_Data!B20 | U5: =Alternatives_Data!B5/Alternatives_Data!B21 | V5: =Alternatives_Data!B5/Alternatives_Data!B22 | W5: =Alternatives_Data!B5/Alternatives_Data!B23 | X5: =Alternatives_Data!B5/Alternatives_Data!B24 | Y5: =Alternatives_Data!B5/Alternatives_Data!B25 | Z5: =Alternatives_Data!B5/Alternatives_Data!B26 | AA5: =Alternatives_Data!B5/Alternatives_Data!B27 | AB5: =Alternatives_Data!B5/Alternatives_Data!B28 | AC5: =Alternatives_Data!B5/Alternatives_Data!B29 | AD5: =Alternatives_Data!B5/Alternatives_Data!B30 | AE5: =Alternatives_Data!B5/Alternatives_Data!B31 | AF5: =Alternatives_Data!B5/Alternatives_Data!B32 | AG5: =Alternatives_Data!B5/Alternatives_Data!B33 | AH5: =Alternatives_Data!B5/Alternatives_Data!B34 | AI5: =Alternatives_Data!B5/Alternatives_Data!B35 | AJ5: =Alternatives_Data!B5/Alternatives_Data!B36 | AK5: =Alternatives_Data!B5/Alternatives_Data!B37 | AL5: =Alternatives_Data!B5/Alternatives_Data!B38 | AM5: =Alternatives_Data!B5/Alternatives_Data!B39 | AN5: =Alternatives_Data!B5/Alternatives_Data!B40 | AO5: =Alternatives_Data!B5/Alternatives_Data!B41 | AP5: =Alternatives_Data!B5/Alternatives_Data!B42 | AQ5: =Alternatives_Data!B5/Alternatives_Data!B43
A6: Eko | B6: =Alternatives_Data!B6/Alternatives_Data!B2 | C6: =Alternatives_Data!B6/Alternatives_Data!B3 | D6: =Alternatives_Data!B6/Alternatives_Data!B4 | E6: =Alternatives_Data!B6/Alternatives_Data!B5 | F6: =Alternatives_Data!B6/Alternatives_Data!B6 | G6: =Alternatives_Data!B6/Alternatives_Data!B7 | H6: =Alternatives_Data!B6/Alternatives_Data!B8 | I6: =Alternatives_Data!B6/Alternatives_Data!B9 | J6: =Alternatives_Data!B6/Alternatives_Data!B10 | K6: =Alternatives_Data!B6/Alternatives_Data!B11 | L6: =Alternatives_Data!B6/Alternatives_Data!B12 | M6: =Alternatives_Data!B6/Alternatives_Data!B13 | N6: =Alternatives_Data!B6/Alternatives_Data!B14 | O6: =Alternatives_Data!B6/Alternatives_Data!B15 | P6: =Alternatives_Data!B6/Alternatives_Data!B16 | Q6: =Alternatives_Data!B6/Alternatives_Data!B17 | R6: =Alternatives_Data!B6/Alternatives_Data!B18 | S6: =Alternatives_Data!B6/Alternatives_Data!B19 | T6: =Alternatives_Data!B6/Alternatives_Data!B20 | U6: =Alternatives_Data!B6/Alternatives_Data!B21 | V6: =Alternatives_Data!B6/Alternatives_Data!B22 | W6: =Alternatives_Data!B6/Alternatives_Data!B23 | X6: =Alternatives_Data!B6/Alternatives_Data!B24 | Y6: =Alternatives_Data!B6/Alternatives_Data!B25 | Z6: =Alternatives_Data!B6/Alternatives_Data!B26 | AA6: =Alternatives_Data!B6/Alternatives_Data!B27 | AB6: =Alternatives_Data!B6/Alternatives_Data!B28 | AC6: =Alternatives_Data!B6/Alternatives_Data!B29 | AD6: =Alternatives_Data!B6/Alternatives_Data!B30 | AE6: =Alternatives_Data!B6/Alternatives_Data!B31 | AF6: =Alternatives_Data!B6/Alternatives_Data!B32 | AG6: =Alternatives_Data!B6/Alternatives_Data!B33 | AH6: =Alternatives_Data!B6/Alternatives_Data!B34 | AI6: =Alternatives_Data!B6/Alternatives_Data!B35 | AJ6: =Alternatives_Data!B6/Alternatives_Data!B36 | AK6: =Alternatives_Data!B6/Alternatives_Data!B37 | AL6: =Alternatives_Data!B6/Alternatives_Data!B38 | AM6: =Alternatives_Data!B6/Alternatives_Data!B39 | AN6: =Alternatives_Data!B6/Alternatives_Data!B40 | AO6: =Alternatives_Data!B6/Alternatives_Data!B41 | AP6: =Alternatives_Data!B6/Alternatives_Data!B42 | AQ6: =Alternatives_Data!B6/Alternatives_Data!B43
A7: Fajar | B7: =Alternatives_Data!B7/Alternatives_Data!B2 | C7: =Alternatives_Data!B7/Alternatives_Data!B3 | D7: =Alternatives_Data!B7/Alternatives_Data!B4 | E7: =Alternatives_Data!B7/Alternatives_Data!B5 | F7: =Alternatives_Data!B7/Alternatives_Data!B6 | G7: =Alternatives_Data!B7/Alternatives_Data!B7 | H7: =Alternatives_Data!B7/Alternatives_Data!B8 | I7: =Alternatives_Data!B7/Alternatives_Data!B9 | J7: =Alternatives_Data!B7/Alternatives_Data!B10 | K7: =Alternatives_Data!B7/Alternatives_Data!B11 | L7: =Alternatives_Data!B7/Alternatives_Data!B12 | M7: =Alternatives_Data!B7/Alternatives_Data!B13 | N7: =Alternatives_Data!B7/Alternatives_Data!B14 | O7: =Alternatives_Data!B7/Alternatives_Data!B15 | P7: =Alternatives_Data!B7/Alternatives_Data!B16 | Q7: =Alternatives_Data!B7/Alternatives_Data!B17 | R7: =Alternatives_Data!B7/Alternatives_Data!B18 | S7: =Alternatives_Data!B7/Alternatives_Data!B19 | T7: =Alternatives_Data!B7/Alternatives_Data!B20 | U7: =Alternatives_Data!B7/Alternatives_Data!B21 | V7: =Alternatives_Data!B7/Alternatives_Data!B22 | W7: =Alternatives_Data!B7/Alternatives_Data!B23 | X7: =Alternatives_Data!B7/Alternatives_Data!B24 | Y7: =Alternatives_Data!B7/Alternatives_Data!B25 | Z7: =Alternatives_Data!B7/Alternatives_Data!B26 | AA7: =Alternatives_Data!B7/Alternatives_Data!B27 | AB7: =Alternatives_Data!B7/Alternatives_Data!B28 | AC7: =Alternatives_Data!B7/Alternatives_Data!B29 | AD7: =Alternatives_Data!B7/Alternatives_Data!B30 | AE7: =Alternatives_Data!B7/Alternatives_Data!B31 | AF7: =Alternatives_Data!B7/Alternatives_Data!B32 | AG7: =Alternatives_Data!B7/Alternatives_Data!B33 | AH7: =Alternatives_Data!B7/Alternatives_Data!B34 | AI7: =Alternatives_Data!B7/Alternatives_Data!B35 | AJ7: =Alternatives_Data!B7/Alternatives_Data!B36 | AK7: =Alternatives_Data!B7/Alternatives_Data!B37 | AL7: =Alternatives_Data!B7/Alternatives_Data!B38 | AM7: =Alternatives_Data!B7/Alternatives_Data!B39 | AN7: =Alternatives_Data!B7/Alternatives_Data!B40 | AO7: =Alternatives_Data!B7/Alternatives_Data!B41 | AP7: =Alternatives_Data!B7/Alternatives_Data!B42 | AQ7: =Alternatives_Data!B7/Alternatives_Data!B43
A8: Gita | B8: =Alternatives_Data!B8/Alternatives_Data!B2 | C8: =Alternatives_Data!B8/Alternatives_Data!B3 | D8: =Alternatives_Data!B8/Alternatives_Data!B4 | E8: =Alternatives_Data!B8/Alternatives_Data!B5 | F8: =Alternatives_Data!B8/Alternatives_Data!B6 | G8: =Alternatives_Data!B8/Alternatives_Data!B7 | H8: =Alternatives_Data!B8/Alternatives_Data!B8 | I8: =Alternatives_Data!B8/Alternatives_Data!B9 | J8: =Alternatives_Data!B8/Alternatives_Data!B10 | K8: =Alternatives_Data!B8/Alternatives_Data!B11 | L8: =Alternatives_Data!B8/Alternatives_Data!B12 | M8: =Alternatives_Data!B8/Alternatives_Data!B13 | N8: =Alternatives_Data!B8/Alternatives_Data!B14 | O8: =Alternatives_Data!B8/Alternatives_Data!B15 | P8: =Alternatives_Data!B8/Alternatives_Data!B16 | Q8: =Alternatives_Data!B8/Alternatives_Data!B17 | R8: =Alternatives_Data!B8/Alternatives_Data!B18 | S8: =Alternatives_Data!B8/Alternatives_Data!B19 | T8: =Alternatives_Data!B8/Alternatives_Data!B20 | U8: =Alternatives_Data!B8/Alternatives_Data!B21 | V8: =Alternatives_Data!B8/Alternatives_Data!B22 | W8: =Alternatives_Data!B8/Alternatives_Data!B23 | X8: =Alternatives_Data!B8/Alternatives_Data!B24 | Y8: =Alternatives_Data!B8/Alternatives_Data!B25 | Z8: =Alternatives_Data!B8/Alternatives_Data!B26 | AA8: =Alternatives_Data!B8/Alternatives_Data!B27 | AB8: =Alternatives_Data!B8/Alternatives_Data!B28 | AC8: =Alternatives_Data!B8/Alternatives_Data!B29 | AD8: =Alternatives_Data!B8/Alternatives_Data!B30 | AE8: =Alternatives_Data!B8/Alternatives_Data!B31 | AF8: =Alternatives_Data!B8/Alternatives_Data!B32 | AG8: =Alternatives_Data!B8/Alternatives_Data!B33 | AH8: =Alternatives_Data!B8/Alternatives_Data!B34 | AI8: =Alternatives_Data!B8/Alternatives_Data!B35 | AJ8: =Alternatives_Data!B8/Alternatives_Data!B36 | AK8: =Alternatives_Data!B8/Alternatives_Data!B37 | AL8: =Alternatives_Data!B8/Alternatives_Data!B38 | AM8: =Alternatives_Data!B8/Alternatives_Data!B39 | AN8: =Alternatives_Data!B8/Alternatives_Data!B40 | AO8: =Alternatives_Data!B8/Alternatives_Data!B41 | AP8: =Alternatives_Data!B8/Alternatives_Data!B42 | AQ8: =Alternatives_Data!B8/Alternatives_Data!B43
A9: Hendra | B9: =Alternatives_Data!B9/Alternatives_Data!B2 | C9: =Alternatives_Data!B9/Alternatives_Data!B3 | D9: =Alternatives_Data!B9/Alternatives_Data!B4 | E9: =Alternatives_Data!B9/Alternatives_Data!B5 | F9: =Alternatives_Data!B9/Alternatives_Data!B6 | G9: =Alternatives_Data!B9/Alternatives_Data!B7 | H9: =Alternatives_Data!B9/Alternatives_Data!B8 | I9: =Alternatives_Data!B9/Alternatives_Data!B9 | J9: =Alternatives_Data!B9/Alternatives_Data!B10 | K9: =Alternatives_Data!B9/Alternatives_Data!B11 | L9: =Alternatives_Data!B9/Alternatives_Data!B12 | M9: =Alternatives_Data!B9/Alternatives_Data!B13 | N9: =Alternatives_Data!B9/Alternatives_Data!B14 | O9: =Alternatives_Data!B9/Alternatives_Data!B15 | P9: =Alternatives_Data!B9/Alternatives_Data!B16 | Q9: =Alternatives_Data!B9/Alternatives_Data!B17 | R9: =Alternatives_Data!B9/Alternatives_Data!B18 | S9: =Alternatives_Data!B9/Alternatives_Data!B19 | T9: =Alternatives_Data!B9/Alternatives_Data!B20 | U9: =Alternatives_Data!B9/Alternatives_Data!B21 | V9: =Alternatives_Data!B9/Alternatives_Data!B22 | W9: =Alternatives_Data!B9/Alternatives_Data!B23 | X9: =Alternatives_Data!B9/Alternatives_Data!B24 | Y9: =Alternatives_Data!B9/Alternatives_Data!B25 | Z9: =Alternatives_Data!B9/Alternatives_Data!B26 | AA9: =Alternatives_Data!B9/Alternatives_Data!B27 | AB9: =Alternatives_Data!B9/Alternatives_Data!B28 | AC9: =Alternatives_Data!B9/Alternatives_Data!B29 | AD9: =Alternatives_Data!B9/Alternatives_Data!B30 | AE9: =Alternatives_Data!B9/Alternatives_Data!B31 | AF9: =Alternatives_Data!B9/Alternatives_Data!B32 | AG9: =Alternatives_Data!B9/Alternatives_Data!B33 | AH9: =Alternatives_Data!B9/Alternatives_Data!B34 | AI9: =Alternatives_Data!B9/Alternatives_Data!B35 | AJ9: =Alternatives_Data!B9/Alternatives_Data!B36 | AK9: =Alternatives_Data!B9/Alternatives_Data!B37 | AL9: =Alternatives_Data!B9/Alternatives_Data!B38 | AM9: =Alternatives_Data!B9/Alternatives_Data!B39 | AN9: =Alternatives_Data!B9/Alternatives_Data!B40 | AO9: =Alternatives_Data!B9/Alternatives_Data!B41 | AP9: =Alternatives_Data!B9/Alternatives_Data!B42 | AQ9: =Alternatives_Data!B9/Alternatives_Data!B43
A10: Intan | B10: =Alternatives_Data!B10/Alternatives_Data!B2 | C10: =Alternatives_Data!B10/Alternatives_Data!B3 | D10: =Alternatives_Data!B10/Alternatives_Data!B4 | E10: =Alternatives_Data!B10/Alternatives_Data!B5 | F10: =Alternatives_Data!B10/Alternatives_Data!B6 | G10: =Alternatives_Data!B10/Alternatives_Data!B7 | H10: =Alternatives_Data!B10/Alternatives_Data!B8 | I10: =Alternatives_Data!B10/Alternatives_Data!B9 | J10: =Alternatives_Data!B10/Alternatives_Data!B10 | K10: =Alternatives_Data!B10/Alternatives_Data!B11 | L10: =Alternatives_Data!B10/Alternatives_Data!B12 | M10: =Alternatives_Data!B10/Alternatives_Data!B13 | N10: =Alternatives_Data!B10/Alternatives_Data!B14 | O10: =Alternatives_Data!B10/Alternatives_Data!B15 | P10: =Alternatives_Data!B10/Alternatives_Data!B16 | Q10: =Alternatives_Data!B10/Alternatives_Data!B17 | R10: =Alternatives_Data!B10/Alternatives_Data!B18 | S10: =Alternatives_Data!B10/Alternatives_Data!B19 | T10: =Alternatives_Data!B10/Alternatives_Data!B20 | U10: =Alternatives_Data!B10/Alternatives_Data!B21 | V10: =Alternatives_Data!B10/Alternatives_Data!B22 | W10: =Alternatives_Data!B10/Alternatives_Data!B23 | X10: =Alternatives_Data!B10/Alternatives_Data!B24 | Y10: =Alternatives_Data!B10/Alternatives_Data!B25 | Z10: =Alternatives_Data!B10/Alternatives_Data!B26 | AA10: =Alternatives_Data!B10/Alternatives_Data!B27 | AB10: =Alternatives_Data!B10/Alternatives_Data!B28 | AC10: =Alternatives_Data!B10/Alternatives_Data!B29 | AD10: =Alternatives_Data!B10/Alternatives_Data!B30 | AE10: =Alternatives_Data!B10/Alternatives_Data!B31 | AF10: =Alternatives_Data!B10/Alternatives_Data!B32 | AG10: =Alternatives_Data!B10/Alternatives_Data!B33 | AH10: =Alternatives_Data!B10/Alternatives_Data!B34 | AI10: =Alternatives_Data!B10/Alternatives_Data!B35 | AJ10: =Alternatives_Data!B10/Alternatives_Data!B36 | AK10: =Alternatives_Data!B10/Alternatives_Data!B37 | AL10: =Alternatives_Data!B10/Alternatives_Data!B38 | AM10: =Alternatives_Data!B10/Alternatives_Data!B39 | AN10: =Alternatives_Data!B10/Alternatives_Data!B40 | AO10: =Alternatives_Data!B10/Alternatives_Data!B41 | AP10: =Alternatives_Data!B10/Alternatives_Data!B42 | AQ10: =Alternatives_Data!B10/Alternatives_Data!B43
A11: Joko | B11: =Alternatives_Data!B11/Alternatives_Data!B2 | C11: =Alternatives_Data!B11/Alternatives_Data!B3 | D11: =Alternatives_Data!B11/Alternatives_Data!B4 | E11: =Alternatives_Data!B11/Alternatives_Data!B5 | F11: =Alternatives_Data!B11/Alternatives_Data!B6 | G11: =Alternatives_Data!B11/Alternatives_Data!B7 | H11: =Alternatives_Data!B11/Alternatives_Data!B8 | I11: =Alternatives_Data!B11/Alternatives_Data!B9 | J11: =Alternatives_Data!B11/Alternatives_Data!B10 | K11: =Alternatives_Data!B11/Alternatives_Data!B11 | L11: =Alternatives_Data!B11/Alternatives_Data!B12 | M11: =Alternatives_Data!B11/Alternatives_Data!B13 | N11: =Alternatives_Data!B11/Alternatives_Data!B14 | O11: =Alternatives_Data!B11/Alternatives_Data!B15 | P11: =Alternatives_Data!B11/Alternatives_Data!B16 | Q11: =Alternatives_Data!B11/Alternatives_Data!B17 | R11: =Alternatives_Data!B11/Alternatives_Data!B18 | S11: =Alternatives_Data!B11/Alternatives_Data!B19 | T11: =Alternatives_Data!B11/Alternatives_Data!B20 | U11: =Alternatives_Data!B11/Alternatives_Data!B21 | V11: =Alternatives_Data!B11/Alternatives_Data!B22 | W11: =Alternatives_Data!B11/Alternatives_Data!B23 | X11: =Alternatives_Data!B11/Alternatives_Data!B24 | Y11: =Alternatives_Data!B11/Alternatives_Data!B25 | Z11: =Alternatives_Data!B11/Alternatives_Data!B26 | AA11: =Alternatives_Data!B11/Alternatives_Data!B27 | AB11: =Alternatives_Data!B11/Alternatives_Data!B28 | AC11: =Alternatives_Data!B11/Alternatives_Data!B29 | AD11: =Alternatives_Data!B11/Alternatives_Data!B30 | AE11: =Alternatives_Data!B11/Alternatives_Data!B31 | AF11: =Alternatives_Data!B11/Alternatives_Data!B32 | AG11: =Alternatives_Data!B11/Alternatives_Data!B33 | AH11: =Alternatives_Data!B11/Alternatives_Data!B34 | AI11: =Alternatives_Data!B11/Alternatives_Data!B35 | AJ11: =Alternatives_Data!B11/Alternatives_Data!B36 | AK11: =Alternatives_Data!B11/Alternatives_Data!B37 | AL11: =Alternatives_Data!B11/Alternatives_Data!B38 | AM11: =Alternatives_Data!B11/Alternatives_Data!B39 | AN11: =Alternatives_Data!B11/Alternatives_Data!B40 | AO11: =Alternatives_Data!B11/Alternatives_Data!B41 | AP11: =Alternatives_Data!B11/Alternatives_Data!B42 | AQ11: =Alternatives_Data!B11/Alternatives_Data!B43
A12: Kiki | B12: =Alternatives_Data!B12/Alternatives_Data!B2 | C12: =Alternatives_Data!B12/Alternatives_Data!B3 | D12: =Alternatives_Data!B12/Alternatives_Data!B4 | E12: =Alternatives_Data!B12/Alternatives_Data!B5 | F12: =Alternatives_Data!B12/Alternatives_Data!B6 | G12: =Alternatives_Data!B12/Alternatives_Data!B7 | H12: =Alternatives_Data!B12/Alternatives_Data!B8 | I12: =Alternatives_Data!B12/Alternatives_Data!B9 | J12: =Alternatives_Data!B12/Alternatives_Data!B10 | K12: =Alternatives_Data!B12/Alternatives_Data!B11 | L12: =Alternatives_Data!B12/Alternatives_Data!B12 | M12: =Alternatives_Data!B12/Alternatives_Data!B13 | N12: =Alternatives_Data!B12/Alternatives_Data!B14 | O12: =Alternatives_Data!B12/Alternatives_Data!B15 | P12: =Alternatives_Data!B12/Alternatives_Data!B16 | Q12: =Alternatives_Data!B12/Alternatives_Data!B17 | R12: =Alternatives_Data!B12/Alternatives_Data!B18 | S12: =Alternatives_Data!B12/Alternatives_Data!B19 | T12: =Alternatives_Data!B12/Alternatives_Data!B20 | U12: =Alternatives_Data!B12/Alternatives_Data!B21 | V12: =Alternatives_Data!B12/Alternatives_Data!B22 | W12: =Alternatives_Data!B12/Alternatives_Data!B23 | X12: =Alternatives_Data!B12/Alternatives_Data!B24 | Y12: =Alternatives_Data!B12/Alternatives_Data!B25 | Z12: =Alternatives_Data!B12/Alternatives_Data!B26 | AA12: =Alternatives_Data!B12/Alternatives_Data!B27 | AB12: =Alternatives_Data!B12/Alternatives_Data!B28 | AC12: =Alternatives_Data!B12/Alternatives_Data!B29 | AD12: =Alternatives_Data!B12/Alternatives_Data!B30 | AE12: =Alternatives_Data!B12/Alternatives_Data!B31 | AF12: =Alternatives_Data!B12/Alternatives_Data!B32 | AG12: =Alternatives_Data!B12/Alternatives_Data!B33 | AH12: =Alternatives_Data!B12/Alternatives_Data!B34 | AI12: =Alternatives_Data!B12/Alternatives_Data!B35 | AJ12: =Alternatives_Data!B12/Alternatives_Data!B36 | AK12: =Alternatives_Data!B12/Alternatives_Data!B37 | AL12: =Alternatives_Data!B12/Alternatives_Data!B38 | AM12: =Alternatives_Data!B12/Alternatives_Data!B39 | AN12: =Alternatives_Data!B12/Alternatives_Data!B40 | AO12: =Alternatives_Data!B12/Alternatives_Data!B41 | AP12: =Alternatives_Data!B12/Alternatives_Data!B42 | AQ12: =Alternatives_Data!B12/Alternatives_Data!B43
A13: Lina | B13: =Alternatives_Data!B13/Alternatives_Data!B2 | C13: =Alternatives_Data!B13/Alternatives_Data!B3 | D13: =Alternatives_Data!B13/Alternatives_Data!B4 | E13: =Alternatives_Data!B13/Alternatives_Data!B5 | F13: =Alternatives_Data!B13/Alternatives_Data!B6 | G13: =Alternatives_Data!B13/Alternatives_Data!B7 | H13: =Alternatives_Data!B13/Alternatives_Data!B8 | I13: =Alternatives_Data!B13/Alternatives_Data!B9 | J13: =Alternatives_Data!B13/Alternatives_Data!B10 | K13: =Alternatives_Data!B13/Alternatives_Data!B11 | L13: =Alternatives_Data!B13/Alternatives_Data!B12 | M13: =Alternatives_Data!B13/Alternatives_Data!B13 | N13: =Alternatives_Data!B13/Alternatives_Data!B14 | O13: =Alternatives_Data!B13/Alternatives_Data!B15 | P13: =Alternatives_Data!B13/Alternatives_Data!B16 | Q13: =Alternatives_Data!B13/Alternatives_Data!B17 | R13: =Alternatives_Data!B13/Alternatives_Data!B18 | S13: =Alternatives_Data!B13/Alternatives_Data!B19 | T13: =Alternatives_Data!B13/Alternatives_Data!B20 | U13: =Alternatives_Data!B13/Alternatives_Data!B21 | V13: =Alternatives_Data!B13/Alternatives_Data!B22 | W13: =Alternatives_Data!B13/Alternatives_Data!B23 | X13: =Alternatives_Data!B13/Alternatives_Data!B24 | Y13: =Alternatives_Data!B13/Alternatives_Data!B25 | Z13: =Alternatives_Data!B13/Alternatives_Data!B26 | AA13: =Alternatives_Data!B13/Alternatives_Data!B27 | AB13: =Alternatives_Data!B13/Alternatives_Data!B28 | AC13: =Alternatives_Data!B13/Alternatives_Data!B29 | AD13: =Alternatives_Data!B13/Alternatives_Data!B30 | AE13: =Alternatives_Data!B13/Alternatives_Data!B31 | AF13: =Alternatives_Data!B13/Alternatives_Data!B32 | AG13: =Alternatives_Data!B13/Alternatives_Data!B33 | AH13: =Alternatives_Data!B13/Alternatives_Data!B34 | AI13: =Alternatives_Data!B13/Alternatives_Data!B35 | AJ13: =Alternatives_Data!B13/Alternatives_Data!B36 | AK13: =Alternatives_Data!B13/Alternatives_Data!B37 | AL13: =Alternatives_Data!B13/Alternatives_Data!B38 | AM13: =Alternatives_Data!B13/Alternatives_Data!B39 | AN13: =Alternatives_Data!B13/Alternatives_Data!B40 | AO13: =Alternatives_Data!B13/Alternatives_Data!B41 | AP13: =Alternatives_Data!B13/Alternatives_Data!B42 | AQ13: =Alternatives_Data!B13/Alternatives_Data!B43
A14: Made | B14: =Alternatives_Data!B14/Alternatives_Data!B2 | C14: =Alternatives_Data!B14/Alternatives_Data!B3 | D14: =Alternatives_Data!B14/Alternatives_Data!B4 | E14: =Alternatives_Data!B14/Alternatives_Data!B5 | F14: =Alternatives_Data!B14/Alternatives_Data!B6 | G14: =Alternatives_Data!B14/Alternatives_Data!B7 | H14: =Alternatives_Data!B14/Alternatives_Data!B8 | I14: =Alternatives_Data!B14/Alternatives_Data!B9 | J14: =Alternatives_Data!B14/Alternatives_Data!B10 | K14: =Alternatives_Data!B14/Alternatives_Data!B11 | L14: =Alternatives_Data!B14/Alternatives_Data!B12 | M14: =Alternatives_Data!B14/Alternatives_Data!B13 | N14: =Alternatives_Data!B14/Alternatives_Data!B14 | O14: =Alternatives_Data!B14/Alternatives_Data!B15 | P14: =Alternatives_Data!B14/Alternatives_Data!B16 | Q14: =Alternatives_Data!B14/Alternatives_Data!B17 | R14: =Alternatives_Data!B14/Alternatives_Data!B18 | S14: =Alternatives_Data!B14/Alternatives_Data!B19 | T14: =Alternatives_Data!B14/Alternatives_Data!B20 | U14: =Alternatives_Data!B14/Alternatives_Data!B21 | V14: =Alternatives_Data!B14/Alternatives_Data!B22 | W14: =Alternatives_Data!B14/Alternatives_Data!B23 | X14: =Alternatives_Data!B14/Alternatives_Data!B24 | Y14: =Alternatives_Data!B14/Alternatives_Data!B25 | Z14: =Alternatives_Data!B14/Alternatives_Data!B26 | AA14: =Alternatives_Data!B14/Alternatives_Data!B27 | AB14: =Alternatives_Data!B14/Alternatives_Data!B28 | AC14: =Alternatives_Data!B14/Alternatives_Data!B29 | AD14: =Alternatives_Data!B14/Alternatives_Data!B30 | AE14: =Alternatives_Data!B14/Alternatives_Data!B31 | AF14: =Alternatives_Data!B14/Alternatives_Data!B32 | AG14: =Alternatives_Data!B14/Alternatives_Data!B33 | AH14: =Alternatives_Data!B14/Alternatives_Data!B34 | AI14: =Alternatives_Data!B14/Alternatives_Data!B35 | AJ14: =Alternatives_Data!B14/Alternatives_Data!B36 | AK14: =Alternatives_Data!B14/Alternatives_Data!B37 | AL14: =Alternatives_Data!B14/Alternatives_Data!B38 | AM14: =Alternatives_Data!B14/Alternatives_Data!B39 | AN14: =Alternatives_Data!B14/Alternatives_Data!B40 | AO14: =Alternatives_Data!B14/Alternatives_Data!B41 | AP14: =Alternatives_Data!B14/Alternatives_Data!B42 | AQ14: =Alternatives_Data!B14/Alternatives_Data!B43
A15: Nisa | B15: =Alternatives_Data!B15/Alternatives_Data!B2 | C15: =Alternatives_Data!B15/Alternatives_Data!B3 | D15: =Alternatives_Data!B15/Alternatives_Data!B4 | E15: =Alternatives_Data!B15/Alternatives_Data!B5 | F15: =Alternatives_Data!B15/Alternatives_Data!B6 | G15: =Alternatives_Data!B15/Alternatives_Data!B7 | H15: =Alternatives_Data!B15/Alternatives_Data!B8 | I15: =Alternatives_Data!B15/Alternatives_Data!B9 | J15: =Alternatives_Data!B15/Alternatives_Data!B10 | K15: =Alternatives_Data!B15/Alternatives_Data!B11 | L15: =Alternatives_Data!B15/Alternatives_Data!B12 | M15: =Alternatives_Data!B15/Alternatives_Data!B13 | N15: =Alternatives_Data!B15/Alternatives_Data!B14 | O15: =Alternatives_Data!B15/Alternatives_Data!B15 | P15: =Alternatives_Data!B15/Alternatives_Data!B16 | Q15: =Alternatives_Data!B15/Alternatives_Data!B17 | R15: =Alternatives_Data!B15/Alternatives_Data!B18 | S15: =Alternatives_Data!B15/Alternatives_Data!B19 | T15: =Alternatives_Data!B15/Alternatives_Data!B20 | U15: =Alternatives_Data!B15/Alternatives_Data!B21 | V15: =Alternatives_Data!B15/Alternatives_Data!B22 | W15: =Alternatives_Data!B15/Alternatives_Data!B23 | X15: =Alternatives_Data!B15/Alternatives_Data!B24 | Y15: =Alternatives_Data!B15/Alternatives_Data!B25 | Z15: =Alternatives_Data!B15/Alternatives_Data!B26 | AA15: =Alternatives_Data!B15/Alternatives_Data!B27 | AB15: =Alternatives_Data!B15/Alternatives_Data!B28 | AC15: =Alternatives_Data!B15/Alternatives_Data!B29 | AD15: =Alternatives_Data!B15/Alternatives_Data!B30 | AE15: =Alternatives_Data!B15/Alternatives_Data!B31 | AF15: =Alternatives_Data!B15/Alternatives_Data!B32 | AG15: =Alternatives_Data!B15/Alternatives_Data!B33 | AH15: =Alternatives_Data!B15/Alternatives_Data!B34 | AI15: =Alternatives_Data!B15/Alternatives_Data!B35 | AJ15: =Alternatives_Data!B15/Alternatives_Data!B36 | AK15: =Alternatives_Data!B15/Alternatives_Data!B37 | AL15: =Alternatives_Data!B15/Alternatives_Data!B38 | AM15: =Alternatives_Data!B15/Alternatives_Data!B39 | AN15: =Alternatives_Data!B15/Alternatives_Data!B40 | AO15: =Alternatives_Data!B15/Alternatives_Data!B41 | AP15: =Alternatives_Data!B15/Alternatives_Data!B42 | AQ15: =Alternatives_Data!B15/Alternatives_Data!B43
A16: Oka | B16: =Alternatives_Data!B16/Alternatives_Data!B2 | C16: =Alternatives_Data!B16/Alternatives_Data!B3 | D16: =Alternatives_Data!B16/Alternatives_Data!B4 | E16: =Alternatives_Data!B16/Alternatives_Data!B5 | F16: =Alternatives_Data!B16/Alternatives_Data!B6 | G16: =Alternatives_Data!B16/Alternatives_Data!B7 | H16: =Alternatives_Data!B16/Alternatives_Data!B8 | I16: =Alternatives_Data!B16/Alternatives_Data!B9 | J16: =Alternatives_Data!B16/Alternatives_Data!B10 | K16: =Alternatives_Data!B16/Alternatives_Data!B11 | L16: =Alternatives_Data!B16/Alternatives_Data!B12 | M16: =Alternatives_Data!B16/Alternatives_Data!B13 | N16: =Alternatives_Data!B16/Alternatives_Data!B14 | O16: =Alternatives_Data!B16/Alternatives_Data!B15 | P16: =Alternatives_Data!B16/Alternatives_Data!B16 | Q16: =Alternatives_Data!B16/Alternatives_Data!B17 | R16: =Alternatives_Data!B16/Alternatives_Data!B18 | S16: =Alternatives_Data!B16/Alternatives_Data!B19 | T16: =Alternatives_Data!B16/Alternatives_Data!B20 | U16: =Alternatives_Data!B16/Alternatives_Data!B21 | V16: =Alternatives_Data!B16/Alternatives_Data!B22 | W16: =Alternatives_Data!B16/Alternatives_Data!B23 | X16: =Alternatives_Data!B16/Alternatives_Data!B24 | Y16: =Alternatives_Data!B16/Alternatives_Data!B25 | Z16: =Alternatives_Data!B16/Alternatives_Data!B26 | AA16: =Alternatives_Data!B16/Alternatives_Data!B27 | AB16: =Alternatives_Data!B16/Alternatives_Data!B28 | AC16: =Alternatives_Data!B16/Alternatives_Data!B29 | AD16: =Alternatives_Data!B16/Alternatives_Data!B30 | AE16: =Alternatives_Data!B16/Alternatives_Data!B31 | AF16: =Alternatives_Data!B16/Alternatives_Data!B32 | AG16: =Alternatives_Data!B16/Alternatives_Data!B33 | AH16: =Alternatives_Data!B16/Alternatives_Data!B34 | AI16: =Alternatives_Data!B16/Alternatives_Data!B35 | AJ16: =Alternatives_Data!B16/Alternatives_Data!B36 | AK16: =Alternatives_Data!B16/Alternatives_Data!B37 | AL16: =Alternatives_Data!B16/Alternatives_Data!B38 | AM16: =Alternatives_Data!B16/Alternatives_Data!B39 | AN16: =Alternatives_Data!B16/Alternatives_Data!B40 | AO16: =Alternatives_Data!B16/Alternatives_Data!B41 | AP16: =Alternatives_Data!B16/Alternatives_Data!B42 | AQ16: =Alternatives_Data!B16/Alternatives_Data!B43
A17: Putra | B17: =Alternatives_Data!B17/Alternatives_Data!B2 | C17: =Alternatives_Data!B17/Alternatives_Data!B3 | D17: =Alternatives_Data!B17/Alternatives_Data!B4 | E17: =Alternatives_Data!B17/Alternatives_Data!B5 | F17: =Alternatives_Data!B17/Alternatives_Data!B6 | G17: =Alternatives_Data!B17/Alternatives_Data!B7 | H17: =Alternatives_Data!B17/Alternatives_Data!B8 | I17: =Alternatives_Data!B17/Alternatives_Data!B9 | J17: =Alternatives_Data!B17/Alternatives_Data!B10 | K17: =Alternatives_Data!B17/Alternatives_Data!B11 | L17: =Alternatives_Data!B17/Alternatives_Data!B12 | M17: =Alternatives_Data!B17/Alternatives_Data!B13 | N17: =Alternatives_Data!B17/Alternatives_Data!B14 | O17: =Alternatives_Data!B17/Alternatives_Data!B15 | P17: =Alternatives_Data!B17/Alternatives_Data!B16 | Q17: =Alternatives_Data!B17/Alternatives_Data!B17 | R17: =Alternatives_Data!B17/Alternatives_Data!B18 | S17: =Alternatives_Data!B17/Alternatives_Data!B19 | T17: =Alternatives_Data!B17/Alternatives_Data!B20 | U17: =Alternatives_Data!B17/Alternatives_Data!B21 | V17: =Alternatives_Data!B17/Alternatives_Data!B22 | W17: =Alternatives_Data!B17/Alternatives_Data!B23 | X17: =Alternatives_Data!B17/Alternatives_Data!B24 | Y17: =Alternatives_Data!B17/Alternatives_Data!B25 | Z17: =Alternatives_Data!B17/Alternatives_Data!B26 | AA17: =Alternatives_Data!B17/Alternatives_Data!B27 | AB17: =Alternatives_Data!B17/Alternatives_Data!B28 | AC17: =Alternatives_Data!B17/Alternatives_Data!B29 | AD17: =Alternatives_Data!B17/Alternatives_Data!B30 | AE17: =Alternatives_Data!B17/Alternatives_Data!B31 | AF17: =Alternatives_Data!B17/Alternatives_Data!B32 | AG17: =Alternatives_Data!B17/Alternatives_Data!B33 | AH17: =Alternatives_Data!B17/Alternatives_Data!B34 | AI17: =Alternatives_Data!B17/Alternatives_Data!B35 | AJ17: =Alternatives_Data!B17/Alternatives_Data!B36 | AK17: =Alternatives_Data!B17/Alternatives_Data!B37 | AL17: =Alternatives_Data!B17/Alternatives_Data!B38 | AM17: =Alternatives_Data!B17/Alternatives_Data!B39 | AN17: =Alternatives_Data!B17/Alternatives_Data!B40 | AO17: =Alternatives_Data!B17/Alternatives_Data!B41 | AP17: =Alternatives_Data!B17/Alternatives_Data!B42 | AQ17: =Alternatives_Data!B17/Alternatives_Data!B43
A18: Qori | B18: =Alternatives_Data!B18/Alternatives_Data!B2 | C18: =Alternatives_Data!B18/Alternatives_Data!B3 | D18: =Alternatives_Data!B18/Alternatives_Data!B4 | E18: =Alternatives_Data!B18/Alternatives_Data!B5 | F18: =Alternatives_Data!B18/Alternatives_Data!B6 | G18: =Alternatives_Data!B18/Alternatives_Data!B7 | H18: =Alternatives_Data!B18/Alternatives_Data!B8 | I18: =Alternatives_Data!B18/Alternatives_Data!B9 | J18: =Alternatives_Data!B18/Alternatives_Data!B10 | K18: =Alternatives_Data!B18/Alternatives_Data!B11 | L18: =Alternatives_Data!B18/Alternatives_Data!B12 | M18: =Alternatives_Data!B18/Alternatives_Data!B13 | N18: =Alternatives_Data!B18/Alternatives_Data!B14 | O18: =Alternatives_Data!B18/Alternatives_Data!B15 | P18: =Alternatives_Data!B18/Alternatives_Data!B16 | Q18: =Alternatives_Data!B18/Alternatives_Data!B17 | R18: =Alternatives_Data!B18/Alternatives_Data!B18 | S18: =Alternatives_Data!B18/Alternatives_Data!B19 | T18: =Alternatives_Data!B18/Alternatives_Data!B20 | U18: =Alternatives_Data!B18/Alternatives_Data!B21 | V18: =Alternatives_Data!B18/Alternatives_Data!B22 | W18: =Alternatives_Data!B18/Alternatives_Data!B23 | X18: =Alternatives_Data!B18/Alternatives_Data!B24 | Y18: =Alternatives_Data!B18/Alternatives_Data!B25 | Z18: =Alternatives_Data!B18/Alternatives_Data!B26 | AA18: =Alternatives_Data!B18/Alternatives_Data!B27 | AB18: =Alternatives_Data!B18/Alternatives_Data!B28 | AC18: =Alternatives_Data!B18/Alternatives_Data!B29 | AD18: =Alternatives_Data!B18/Alternatives_Data!B30 | AE18: =Alternatives_Data!B18/Alternatives_Data!B31 | AF18: =Alternatives_Data!B18/Alternatives_Data!B32 | AG18: =Alternatives_Data!B18/Alternatives_Data!B33 | AH18: =Alternatives_Data!B18/Alternatives_Data!B34 | AI18: =Alternatives_Data!B18/Alternatives_Data!B35 | AJ18: =Alternatives_Data!B18/Alternatives_Data!B36 | AK18: =Alternatives_Data!B18/Alternatives_Data!B37 | AL18: =Alternatives_Data!B18/Alternatives_Data!B38 | AM18: =Alternatives_Data!B18/Alternatives_Data!B39 | AN18: =Alternatives_Data!B18/Alternatives_Data!B40 | AO18: =Alternatives_Data!B18/Alternatives_Data!B41 | AP18: =Alternatives_Data!B18/Alternatives_Data!B42 | AQ18: =Alternatives_Data!B18/Alternatives_Data!B43
A19: Rian | B19: =Alternatives_Data!B19/Alternatives_Data!B2 | C19: =Alternatives_Data!B19/Alternatives_Data!B3 | D19: =Alternatives_Data!B19/Alternatives_Data!B4 | E19: =Alternatives_Data!B19/Alternatives_Data!B5 | F19: =Alternatives_Data!B19/Alternatives_Data!B6 | G19: =Alternatives_Data!B19/Alternatives_Data!B7 | H19: =Alternatives_Data!B19/Alternatives_Data!B8 | I19: =Alternatives_Data!B19/Alternatives_Data!B9 | J19: =Alternatives_Data!B19/Alternatives_Data!B10 | K19: =Alternatives_Data!B19/Alternatives_Data!B11 | L19: =Alternatives_Data!B19/Alternatives_Data!B12 | M19: =Alternatives_Data!B19/Alternatives_Data!B13 | N19: =Alternatives_Data!B19/Alternatives_Data!B14 | O19: =Alternatives_Data!B19/Alternatives_Data!B15 | P19: =Alternatives_Data!B19/Alternatives_Data!B16 | Q19: =Alternatives_Data!B19/Alternatives_Data!B17 | R19: =Alternatives_Data!B19/Alternatives_Data!B18 | S19: =Alternatives_Data!B19/Alternatives_Data!B19 | T19: =Alternatives_Data!B19/Alternatives_Data!B20 | U19: =Alternatives_Data!B19/Alternatives_Data!B21 | V19: =Alternatives_Data!B19/Alternatives_Data!B22 | W19: =Alternatives_Data!B19/Alternatives_Data!B23 | X19: =Alternatives_Data!B19/Alternatives_Data!B24 | Y19: =Alternatives_Data!B19/Alternatives_Data!B25 | Z19: =Alternatives_Data!B19/Alternatives_Data!B26 | AA19: =Alternatives_Data!B19/Alternatives_Data!B27 | AB19: =Alternatives_Data!B19/Alternatives_Data!B28 | AC19: =Alternatives_Data!B19/Alternatives_Data!B29 | AD19: =Alternatives_Data!B19/Alternatives_Data!B30 | AE19: =Alternatives_Data!B19/Alternatives_Data!B31 | AF19: =Alternatives_Data!B19/Alternatives_Data!B32 | AG19: =Alternatives_Data!B19/Alternatives_Data!B33 | AH19: =Alternatives_Data!B19/Alternatives_Data!B34 | AI19: =Alternatives_Data!B19/Alternatives_Data!B35 | AJ19: =Alternatives_Data!B19/Alternatives_Data!B36 | AK19: =Alternatives_Data!B19/Alternatives_Data!B37 | AL19: =Alternatives_Data!B19/Alternatives_Data!B38 | AM19: =Alternatives_Data!B19/Alternatives_Data!B39 | AN19: =Alternatives_Data!B19/Alternatives_Data!B40 | AO19: =Alternatives_Data!B19/Alternatives_Data!B41 | AP19: =Alternatives_Data!B19/Alternatives_Data!B42 | AQ19: =Alternatives_Data!B19/Alternatives_Data!B43
A20: Sinta | B20: =Alternatives_Data!B20/Alternatives_Data!B2 | C20: =Alternatives_Data!B20/Alternatives_Data!B3 | D20: =Alternatives_Data!B20/Alternatives_Data!B4 | E20: =Alternatives_Data!B20/Alternatives_Data!B5 | F20: =Alternatives_Data!B20/Alternatives_Data!B6 | G20: =Alternatives_Data!B20/Alternatives_Data!B7 | H20: =Alternatives_Data!B20/Alternatives_Data!B8 | I20: =Alternatives_Data!B20/Alternatives_Data!B9 | J20: =Alternatives_Data!B20/Alternatives_Data!B10 | K20: =Alternatives_Data!B20/Alternatives_Data!B11 | L20: =Alternatives_Data!B20/Alternatives_Data!B12 | M20: =Alternatives_Data!B20/Alternatives_Data!B13 | N20: =Alternatives_Data!B20/Alternatives_Data!B14 | O20: =Alternatives_Data!B20/Alternatives_Data!B15 | P20: =Alternatives_Data!B20/Alternatives_Data!B16 | Q20: =Alternatives_Data!B20/Alternatives_Data!B17 | R20: =Alternatives_Data!B20/Alternatives_Data!B18 | S20: =Alternatives_Data!B20/Alternatives_Data!B19 | T20: =Alternatives_Data!B20/Alternatives_Data!B20 | U20: =Alternatives_Data!B20/Alternatives_Data!B21 | V20: =Alternatives_Data!B20/Alternatives_Data!B22 | W20: =Alternatives_Data!B20/Alternatives_Data!B23 | X20: =Alternatives_Data!B20/Alternatives_Data!B24 | Y20: =Alternatives_Data!B20/Alternatives_Data!B25 | Z20: =Alternatives_Data!B20/Alternatives_Data!B26 | AA20: =Alternatives_Data!B20/Alternatives_Data!B27 | AB20: =Alternatives_Data!B20/Alternatives_Data!B28 | AC20: =Alternatives_Data!B20/Alternatives_Data!B29 | AD20: =Alternatives_Data!B20/Alternatives_Data!B30 | AE20: =Alternatives_Data!B20/Alternatives_Data!B31 | AF20: =Alternatives_Data!B20/Alternatives_Data!B32 | AG20: =Alternatives_Data!B20/Alternatives_Data!B33 | AH20: =Alternatives_Data!B20/Alternatives_Data!B34 | AI20: =Alternatives_Data!B20/Alternatives_Data!B35 | AJ20: =Alternatives_Data!B20/Alternatives_Data!B36 | AK20: =Alternatives_Data!B20/Alternatives_Data!B37 | AL20: =Alternatives_Data!B20/Alternatives_Data!B38 | AM20: =Alternatives_Data!B20/Alternatives_Data!B39 | AN20: =Alternatives_Data!B20/Alternatives_Data!B40 | AO20: =Alternatives_Data!B20/Alternatives_Data!B41 | AP20: =Alternatives_Data!B20/Alternatives_Data!B42 | AQ20: =Alternatives_Data!B20/Alternatives_Data!B43
A21: Tono | B21: =Alternatives_Data!B21/Alternatives_Data!B2 | C21: =Alternatives_Data!B21/Alternatives_Data!B3 | D21: =Alternatives_Data!B21/Alternatives_Data!B4 | E21: =Alternatives_Data!B21/Alternatives_Data!B5 | F21: =Alternatives_Data!B21/Alternatives_Data!B6 | G21: =Alternatives_Data!B21/Alternatives_Data!B7 | H21: =Alternatives_Data!B21/Alternatives_Data!B8 | I21: =Alternatives_Data!B21/Alternatives_Data!B9 | J21: =Alternatives_Data!B21/Alternatives_Data!B10 | K21: =Alternatives_Data!B21/Alternatives_Data!B11 | L21: =Alternatives_Data!B21/Alternatives_Data!B12 | M21: =Alternatives_Data!B21/Alternatives_Data!B13 | N21: =Alternatives_Data!B21/Alternatives_Data!B14 | O21: =Alternatives_Data!B21/Alternatives_Data!B15 | P21: =Alternatives_Data!B21/Alternatives_Data!B16 | Q21: =Alternatives_Data!B21/Alternatives_Data!B17 | R21: =Alternatives_Data!B21/Alternatives_Data!B18 | S21: =Alternatives_Data!B21/Alternatives_Data!B19 | T21: =Alternatives_Data!B21/Alternatives_Data!B20 | U21: =Alternatives_Data!B21/Alternatives_Data!B21 | V21: =Alternatives_Data!B21/Alternatives_Data!B22 | W21: =Alternatives_Data!B21/Alternatives_Data!B23 | X21: =Alternatives_Data!B21/Alternatives_Data!B24 | Y21: =Alternatives_Data!B21/Alternatives_Data!B25 | Z21: =Alternatives_Data!B21/Alternatives_Data!B26 | AA21: =Alternatives_Data!B21/Alternatives_Data!B27 | AB21: =Alternatives_Data!B21/Alternatives_Data!B28 | AC21: =Alternatives_Data!B21/Alternatives_Data!B29 | AD21: =Alternatives_Data!B21/Alternatives_Data!B30 | AE21: =Alternatives_Data!B21/Alternatives_Data!B31 | AF21: =Alternatives_Data!B21/Alternatives_Data!B32 | AG21: =Alternatives_Data!B21/Alternatives_Data!B33 | AH21: =Alternatives_Data!B21/Alternatives_Data!B34 | AI21: =Alternatives_Data!B21/Alternatives_Data!B35 | AJ21: =Alternatives_Data!B21/Alternatives_Data!B36 | AK21: =Alternatives_Data!B21/Alternatives_Data!B37 | AL21: =Alternatives_Data!B21/Alternatives_Data!B38 | AM21: =Alternatives_Data!B21/Alternatives_Data!B39 | AN21: =Alternatives_Data!B21/Alternatives_Data!B40 | AO21: =Alternatives_Data!B21/Alternatives_Data!B41 | AP21: =Alternatives_Data!B21/Alternatives_Data!B42 | AQ21: =Alternatives_Data!B21/Alternatives_Data!B43
A22: Uli | B22: =Alternatives_Data!B22/Alternatives_Data!B2 | C22: =Alternatives_Data!B22/Alternatives_Data!B3 | D22: =Alternatives_Data!B22/Alternatives_Data!B4 | E22: =Alternatives_Data!B22/Alternatives_Data!B5 | F22: =Alternatives_Data!B22/Alternatives_Data!B6 | G22: =Alternatives_Data!B22/Alternatives_Data!B7 | H22: =Alternatives_Data!B22/Alternatives_Data!B8 | I22: =Alternatives_Data!B22/Alternatives_Data!B9 | J22: =Alternatives_Data!B22/Alternatives_Data!B10 | K22: =Alternatives_Data!B22/Alternatives_Data!B11 | L22: =Alternatives_Data!B22/Alternatives_Data!B12 | M22: =Alternatives_Data!B22/Alternatives_Data!B13 | N22: =Alternatives_Data!B22/Alternatives_Data!B14 | O22: =Alternatives_Data!B22/Alternatives_Data!B15 | P22: =Alternatives_Data!B22/Alternatives_Data!B16 | Q22: =Alternatives_Data!B22/Alternatives_Data!B17 | R22: =Alternatives_Data!B22/Alternatives_Data!B18 | S22: =Alternatives_Data!B22/Alternatives_Data!B19 | T22: =Alternatives_Data!B22/Alternatives_Data!B20 | U22: =Alternatives_Data!B22/Alternatives_Data!B21 | V22: =Alternatives_Data!B22/Alternatives_Data!B22 | W22: =Alternatives_Data!B22/Alternatives_Data!B23 | X22: =Alternatives_Data!B22/Alternatives_Data!B24 | Y22: =Alternatives_Data!B22/Alternatives_Data!B25 | Z22: =Alternatives_Data!B22/Alternatives_Data!B26 | AA22: =Alternatives_Data!B22/Alternatives_Data!B27 | AB22: =Alternatives_Data!B22/Alternatives_Data!B28 | AC22: =Alternatives_Data!B22/Alternatives_Data!B29 | AD22: =Alternatives_Data!B22/Alternatives_Data!B30 | AE22: =Alternatives_Data!B22/Alternatives_Data!B31 | AF22: =Alternatives_Data!B22/Alternatives_Data!B32 | AG22: =Alternatives_Data!B22/Alternatives_Data!B33 | AH22: =Alternatives_Data!B22/Alternatives_Data!B34 | AI22: =Alternatives_Data!B22/Alternatives_Data!B35 | AJ22: =Alternatives_Data!B22/Alternatives_Data!B36 | AK22: =Alternatives_Data!B22/Alternatives_Data!B37 | AL22: =Alternatives_Data!B22/Alternatives_Data!B38 | AM22: =Alternatives_Data!B22/Alternatives_Data!B39 | AN22: =Alternatives_Data!B22/Alternatives_Data!B40 | AO22: =Alternatives_Data!B22/Alternatives_Data!B41 | AP22: =Alternatives_Data!B22/Alternatives_Data!B42 | AQ22: =Alternatives_Data!B22/Alternatives_Data!B43
A23: Vina | B23: =Alternatives_Data!B23/Alternatives_Data!B2 | C23: =Alternatives_Data!B23/Alternatives_Data!B3 | D23: =Alternatives_Data!B23/Alternatives_Data!B4 | E23: =Alternatives_Data!B23/Alternatives_Data!B5 | F23: =Alternatives_Data!B23/Alternatives_Data!B6 | G23: =Alternatives_Data!B23/Alternatives_Data!B7 | H23: =Alternatives_Data!B23/Alternatives_Data!B8 | I23: =Alternatives_Data!B23/Alternatives_Data!B9 | J23: =Alternatives_Data!B23/Alternatives_Data!B10 | K23: =Alternatives_Data!B23/Alternatives_Data!B11 | L23: =Alternatives_Data!B23/Alternatives_Data!B12 | M23: =Alternatives_Data!B23/Alternatives_Data!B13 | N23: =Alternatives_Data!B23/Alternatives_Data!B14 | O23: =Alternatives_Data!B23/Alternatives_Data!B15 | P23: =Alternatives_Data!B23/Alternatives_Data!B16 | Q23: =Alternatives_Data!B23/Alternatives_Data!B17 | R23: =Alternatives_Data!B23/Alternatives_Data!B18 | S23: =Alternatives_Data!B23/Alternatives_Data!B19 | T23: =Alternatives_Data!B23/Alternatives_Data!B20 | U23: =Alternatives_Data!B23/Alternatives_Data!B21 | V23: =Alternatives_Data!B23/Alternatives_Data!B22 | W23: =Alternatives_Data!B23/Alternatives_Data!B23 | X23: =Alternatives_Data!B23/Alternatives_Data!B24 | Y23: =Alternatives_Data!B23/Alternatives_Data!B25 | Z23: =Alternatives_Data!B23/Alternatives_Data!B26 | AA23: =Alternatives_Data!B23/Alternatives_Data!B27 | AB23: =Alternatives_Data!B23/Alternatives_Data!B28 | AC23: =Alternatives_Data!B23/Alternatives_Data!B29 | AD23: =Alternatives_Data!B23/Alternatives_Data!B30 | AE23: =Alternatives_Data!B23/Alternatives_Data!B31 | AF23: =Alternatives_Data!B23/Alternatives_Data!B32 | AG23: =Alternatives_Data!B23/Alternatives_Data!B33 | AH23: =Alternatives_Data!B23/Alternatives_Data!B34 | AI23: =Alternatives_Data!B23/Alternatives_Data!B35 | AJ23: =Alternatives_Data!B23/Alternatives_Data!B36 | AK23: =Alternatives_Data!B23/Alternatives_Data!B37 | AL23: =Alternatives_Data!B23/Alternatives_Data!B38 | AM23: =Alternatives_Data!B23/Alternatives_Data!B39 | AN23: =Alternatives_Data!B23/Alternatives_Data!B40 | AO23: =Alternatives_Data!B23/Alternatives_Data!B41 | AP23: =Alternatives_Data!B23/Alternatives_Data!B42 | AQ23: =Alternatives_Data!B23/Alternatives_Data!B43
A24: Wahyu | B24: =Alternatives_Data!B24/Alternatives_Data!B2 | C24: =Alternatives_Data!B24/Alternatives_Data!B3 | D24: =Alternatives_Data!B24/Alternatives_Data!B4 | E24: =Alternatives_Data!B24/Alternatives_Data!B5 | F24: =Alternatives_Data!B24/Alternatives_Data!B6 | G24: =Alternatives_Data!B24/Alternatives_Data!B7 | H24: =Alternatives_Data!B24/Alternatives_Data!B8 | I24: =Alternatives_Data!B24/Alternatives_Data!B9 | J24: =Alternatives_Data!B24/Alternatives_Data!B10 | K24: =Alternatives_Data!B24/Alternatives_Data!B11 | L24: =Alternatives_Data!B24/Alternatives_Data!B12 | M24: =Alternatives_Data!B24/Alternatives_Data!B13 | N24: =Alternatives_Data!B24/Alternatives_Data!B14 | O24: =Alternatives_Data!B24/Alternatives_Data!B15 | P24: =Alternatives_Data!B24/Alternatives_Data!B16 | Q24: =Alternatives_Data!B24/Alternatives_Data!B17 | R24: =Alternatives_Data!B24/Alternatives_Data!B18 | S24: =Alternatives_Data!B24/Alternatives_Data!B19 | T24: =Alternatives_Data!B24/Alternatives_Data!B20 | U24: =Alternatives_Data!B24/Alternatives_Data!B21 | V24: =Alternatives_Data!B24/Alternatives_Data!B22 | W24: =Alternatives_Data!B24/Alternatives_Data!B23 | X24: =Alternatives_Data!B24/Alternatives_Data!B24 | Y24: =Alternatives_Data!B24/Alternatives_Data!B25 | Z24: =Alternatives_Data!B24/Alternatives_Data!B26 | AA24: =Alternatives_Data!B24/Alternatives_Data!B27 | AB24: =Alternatives_Data!B24/Alternatives_Data!B28 | AC24: =Alternatives_Data!B24/Alternatives_Data!B29 | AD24: =Alternatives_Data!B24/Alternatives_Data!B30 | AE24: =Alternatives_Data!B24/Alternatives_Data!B31 | AF24: =Alternatives_Data!B24/Alternatives_Data!B32 | AG24: =Alternatives_Data!B24/Alternatives_Data!B33 | AH24: =Alternatives_Data!B24/Alternatives_Data!B34 | AI24: =Alternatives_Data!B24/Alternatives_Data!B35 | AJ24: =Alternatives_Data!B24/Alternatives_Data!B36 | AK24: =Alternatives_Data!B24/Alternatives_Data!B37 | AL24: =Alternatives_Data!B24/Alternatives_Data!B38 | AM24: =Alternatives_Data!B24/Alternatives_Data!B39 | AN24: =Alternatives_Data!B24/Alternatives_Data!B40 | AO24: =Alternatives_Data!B24/Alternatives_Data!B41 | AP24: =Alternatives_Data!B24/Alternatives_Data!B42 | AQ24: =Alternatives_Data!B24/Alternatives_Data!B43
A25: Xena | B25: =Alternatives_Data!B25/Alternatives_Data!B2 | C25: =Alternatives_Data!B25/Alternatives_Data!B3 | D25: =Alternatives_Data!B25/Alternatives_Data!B4 | E25: =Alternatives_Data!B25/Alternatives_Data!B5 | F25: =Alternatives_Data!B25/Alternatives_Data!B6 | G25: =Alternatives_Data!B25/Alternatives_Data!B7 | H25: =Alternatives_Data!B25/Alternatives_Data!B8 | I25: =Alternatives_Data!B25/Alternatives_Data!B9 | J25: =Alternatives_Data!B25/Alternatives_Data!B10 | K25: =Alternatives_Data!B25/Alternatives_Data!B11 | L25: =Alternatives_Data!B25/Alternatives_Data!B12 | M25: =Alternatives_Data!B25/Alternatives_Data!B13 | N25: =Alternatives_Data!B25/Alternatives_Data!B14 | O25: =Alternatives_Data!B25/Alternatives_Data!B15 | P25: =Alternatives_Data!B25/Alternatives_Data!B16 | Q25: =Alternatives_Data!B25/Alternatives_Data!B17 | R25: =Alternatives_Data!B25/Alternatives_Data!B18 | S25: =Alternatives_Data!B25/Alternatives_Data!B19 | T25: =Alternatives_Data!B25/Alternatives_Data!B20 | U25: =Alternatives_Data!B25/Alternatives_Data!B21 | V25: =Alternatives_Data!B25/Alternatives_Data!B22 | W25: =Alternatives_Data!B25/Alternatives_Data!B23 | X25: =Alternatives_Data!B25/Alternatives_Data!B24 | Y25: =Alternatives_Data!B25/Alternatives_Data!B25 | Z25: =Alternatives_Data!B25/Alternatives_Data!B26 | AA25: =Alternatives_Data!B25/Alternatives_Data!B27 | AB25: =Alternatives_Data!B25/Alternatives_Data!B28 | AC25: =Alternatives_Data!B25/Alternatives_Data!B29 | AD25: =Alternatives_Data!B25/Alternatives_Data!B30 | AE25: =Alternatives_Data!B25/Alternatives_Data!B31 | AF25: =Alternatives_Data!B25/Alternatives_Data!B32 | AG25: =Alternatives_Data!B25/Alternatives_Data!B33 | AH25: =Alternatives_Data!B25/Alternatives_Data!B34 | AI25: =Alternatives_Data!B25/Alternatives_Data!B35 | AJ25: =Alternatives_Data!B25/Alternatives_Data!B36 | AK25: =Alternatives_Data!B25/Alternatives_Data!B37 | AL25: =Alternatives_Data!B25/Alternatives_Data!B38 | AM25: =Alternatives_Data!B25/Alternatives_Data!B39 | AN25: =Alternatives_Data!B25/Alternatives_Data!B40 | AO25: =Alternatives_Data!B25/Alternatives_Data!B41 | AP25: =Alternatives_Data!B25/Alternatives_Data!B42 | AQ25: =Alternatives_Data!B25/Alternatives_Data!B43
A26: Yoga | B26: =Alternatives_Data!B26/Alternatives_Data!B2 | C26: =Alternatives_Data!B26/Alternatives_Data!B3 | D26: =Alternatives_Data!B26/Alternatives_Data!B4 | E26: =Alternatives_Data!B26/Alternatives_Data!B5 | F26: =Alternatives_Data!B26/Alternatives_Data!B6 | G26: =Alternatives_Data!B26/Alternatives_Data!B7 | H26: =Alternatives_Data!B26/Alternatives_Data!B8 | I26: =Alternatives_Data!B26/Alternatives_Data!B9 | J26: =Alternatives_Data!B26/Alternatives_Data!B10 | K26: =Alternatives_Data!B26/Alternatives_Data!B11 | L26: =Alternatives_Data!B26/Alternatives_Data!B12 | M26: =Alternatives_Data!B26/Alternatives_Data!B13 | N26: =Alternatives_Data!B26/Alternatives_Data!B14 | O26: =Alternatives_Data!B26/Alternatives_Data!B15 | P26: =Alternatives_Data!B26/Alternatives_Data!B16 | Q26: =Alternatives_Data!B26/Alternatives_Data!B17 | R26: =Alternatives_Data!B26/Alternatives_Data!B18 | S26: =Alternatives_Data!B26/Alternatives_Data!B19 | T26: =Alternatives_Data!B26/Alternatives_Data!B20 | U26: =Alternatives_Data!B26/Alternatives_Data!B21 | V26: =Alternatives_Data!B26/Alternatives_Data!B22 | W26: =Alternatives_Data!B26/Alternatives_Data!B23 | X26: =Alternatives_Data!B26/Alternatives_Data!B24 | Y26: =Alternatives_Data!B26/Alternatives_Data!B25 | Z26: =Alternatives_Data!B26/Alternatives_Data!B26 | AA26: =Alternatives_Data!B26/Alternatives_Data!B27 | AB26: =Alternatives_Data!B26/Alternatives_Data!B28 | AC26: =Alternatives_Data!B26/Alternatives_Data!B29 | AD26: =Alternatives_Data!B26/Alternatives_Data!B30 | AE26: =Alternatives_Data!B26/Alternatives_Data!B31 | AF26: =Alternatives_Data!B26/Alternatives_Data!B32 | AG26: =Alternatives_Data!B26/Alternatives_Data!B33 | AH26: =Alternatives_Data!B26/Alternatives_Data!B34 | AI26: =Alternatives_Data!B26/Alternatives_Data!B35 | AJ26: =Alternatives_Data!B26/Alternatives_Data!B36 | AK26: =Alternatives_Data!B26/Alternatives_Data!B37 | AL26: =Alternatives_Data!B26/Alternatives_Data!B38 | AM26: =Alternatives_Data!B26/Alternatives_Data!B39 | AN26: =Alternatives_Data!B26/Alternatives_Data!B40 | AO26: =Alternatives_Data!B26/Alternatives_Data!B41 | AP26: =Alternatives_Data!B26/Alternatives_Data!B42 | AQ26: =Alternatives_Data!B26/Alternatives_Data!B43
